Workbook

Sheet 📋 SEND CLIENT
C2: PRODUCT CONTROL
C5: =NOW() -> 46196.469
B6: 📦 TATA — ORDER DATA
B7: Vulcan Order (PO) | C7: Material | D7: Designation | F7: Order Date | G7: ETA to TETE | H7: Qty Ordered
B8: ='📋 ORDERS'!E4 -> 4300034814 | C8: ='📋 ORDERS'!F4 -> 15643491 | D8: ='📋 ORDERS'!G4 -> HA 3128 | E8: ='📋 ORDERS'!H4 -> BRG BUSHING ADAPTER 125.41MM HA 3128 SKF | F8: ='📋 ORDERS'!I4 -> 46057 | G8: 46181 | H8: ='📋 ORDERS'!L4 -> 4
B9: ='📋 ORDERS'!E5 -> 4300034814 | C9: ='📋 ORDERS'!F5 -> 13040369 | D9: ='📋 ORDERS'!G5 -> COP.ATL160M | E9: ='📋 ORDERS'!H5 -> LABYRINTH SEAL 160MMATL TIMKEN | F9: ='📋 ORDERS'!I5 -> 46057 | G9: 46181 | H9: ='📋 ORDERS'!L5 -> 2
B10: ='📋 ORDERS'!E6 -> 4300034814 | C10: ='📋 ORDERS'!F6 -> 15153568 | D10: ='📋 ORDERS'!G6 -> COP.01EB180MGR | E10: ='📋 ORDERS'!H6 -> BALL BRNG 01 B 180MM GR COOPER | F10: ='📋 ORDERS'!I6 -> 46057 | G10: 46181 | H10: ='📋 ORDERS'!L6 -> 2
B11: ='📋 ORDERS'!E7 -> 0 | C11: ='📋 ORDERS'!F7 -> 15002466 | D11: ='📋 ORDERS'!G7 -> 6322/C3VL0241 | E11: ='📋 ORDERS'!H7 -> DEEP GROOVE BALL BEARING - INSOCOAT 6322 | F11: ='📋 ORDERS'!I7 -> 46056 | G11: 46181 | H11: ='📋 ORDERS'!L7 -> 2
B12: ='📋 ORDERS'!E8 -> 4300033496 | C12: ='📋 ORDERS'!F8 -> 15501296 | D12: ='📋 ORDERS'!G8 -> COP.01EB125MGR | E12: ='📋 ORDERS'!H8 -> CYL ROLL BRG 01 B 125M GR COOPER | F12: ='📋 ORDERS'!I8 -> 46014 | G12: Read to Deliver | H12: ='📋 ORDERS'!L8 -> 1
B13: ='📋 ORDERS'!E9 -> 4300033496 | C13: ='📋 ORDERS'!F9 -> 13188279 | D13: ='📋 ORDERS'!G9 -> COP.01EB180MGR | E13: ='📋 ORDERS'!H9 -> CL RL BRG 01 B 180M GR COOPER BEARINGS | F13: ='📋 ORDERS'!I9 -> 46014 | G13: Read to Deliver | H13: ='📋 ORDERS'!L9 -> 3
B14: ='📋 ORDERS'!E10 -> 0 | C14: ='📋 ORDERS'!F10 -> 13188470 | D14: ='📋 ORDERS'!G10 -> COP.01EB140MGR | E14: ='📋 ORDERS'!H10 -> CL RL BRG 01 B 140M GR COOPER BEARINGS | F14: ='📋 ORDERS'!I10 -> 46161 | G14: 46268 | H14: ='📋 ORDERS'!L10 -> 1
B15: ='📋 ORDERS'!E11 -> 0 | C15: ='📋 ORDERS'!F11 -> 13040555 | D15: ='📋 ORDERS'!G11 -> COP.02EB180MGR | E15: ='📋 ORDERS'!H11 -> CL RL BRG 02 B 180M GR COOPER BEARINGS | F15: ='📋 ORDERS'!I11 -> 46161 | G15: 46268 | H15: ='📋 ORDERS'!L11 -> 5
B16: ='📋 ORDERS'!E12 -> 0 | C16: ='📋 ORDERS'!F12 -> 13040555 | D16: ='📋 ORDERS'!G12 -> COP.02EB180MGR | E16: ='📋 ORDERS'!H12 -> CL RL BRG 02 B 180M GR COOPER BEARINGS | F16: ='📋 ORDERS'!I12 -> 46161 | G16: 46268 | H16: ='📋 ORDERS'!L12 -> 2
B17: ='📋 ORDERS'!E13 -> 0 | C17: ='📋 ORDERS'!F13 -> 13188470 | D17: ='📋 ORDERS'!G13 -> COP.01EB140MGR | E17: ='📋 ORDERS'!H13 -> CL RL BRG 01 B 140M GR COOPER BEARINGS | F17: ='📋 ORDERS'!I13 -> 46161 | G17: 46268 | H17: ='📋 ORDERS'!L13 -> 1
B18: ='📋 ORDERS'!E14 -> 4300037223 | C18: ='📋 ORDERS'!F14 -> 15134397 | D18: ='📋 ORDERS'!G14 -> SRV.NU 407 | E18: ='📋 ORDERS'!H14 -> CYL ROL BEARING | F18: ='📋 ORDERS'!I14 -> 46154 | G18: 46254 | H18: ='📋 ORDERS'!L14 -> 3
B19: ='📋 ORDERS'!E15 -> 4300037815 | C19: ='📋 ORDERS'!F15 -> 13040555 | D19: ='📋 ORDERS'!G15 -> COP.02EB180MGR | E19: ='📋 ORDERS'!H15 -> CYL ROLL BRG MSM180BR TIMKEN | F19: ='📋 ORDERS'!I15 -> 46154 | G19: 46261 | H19: ='📋 ORDERS'!L15 -> 2
B20: ='📋 ORDERS'!E16 -> 4300037815 | C20: ='📋 ORDERS'!F16 -> 13040485 | D20: ='📋 ORDERS'!G16 -> COP.02EB220MGR | E20: ='📋 ORDERS'!H16 -> CYL ROLL BRG MSM220BR TIMKEN | F20: ='📋 ORDERS'!I16 -> 46154 | G20: 46261 | H20: ='📋 ORDERS'!L16 -> 1
B21: ='📋 ORDERS'!E17 -> 4300037815 | C21: ='📋 ORDERS'!F17 -> 13040555 | D21: ='📋 ORDERS'!G17 -> COP.02EB180MGR | E21: ='📋 ORDERS'!H17 -> CYL ROLL BRG MSM180BR TIMKEN | F21: ='📋 ORDERS'!I17 -> 46154 | G21: 46261 | H21: ='📋 ORDERS'!L17 -> 7
B22: ='📋 ORDERS'!E18 -> 4300037815 | C22: ='📋 ORDERS'!F18 -> 15509234 | D22: ='📋 ORDERS'!G18 -> 70X110X10 HMSA10 RG | E22: ='📋 ORDERS'!H18 -> LIP SEAL FKM 70MM 110MM | F22: ='📋 ORDERS'!I18 -> 46154 | G22: 46268 | H22: ='📋 ORDERS'!L18 -> 12
B23: ='📋 ORDERS'!E19 -> 4300034374 | C23: ='📋 ORDERS'!F19 -> 15744967 | D23: ='📋 ORDERS'!G19 -> 24152 CC/W33 | E23: ='📋 ORDERS'!H19 -> BEARING 24152 CC/W33 SKF | F23: ='📋 ORDERS'!I19 -> 46113 | G23: 46275 | H23: ='📋 ORDERS'!L19 -> 5
B24: ='📋 ORDERS'!E20 -> 4300034374 | C24: ='📋 ORDERS'!F20 -> 15744967 | D24: ='📋 ORDERS'!G20 -> 24152 CC/W33 | E24: ='📋 ORDERS'!H20 -> BEARING 24152 CC/W33 SKF | F24: ='📋 ORDERS'!I20 -> 46113 | G24: 46275 | H24: ='📋 ORDERS'!L20 -> 4
B25: ='📋 ORDERS'!E21 -> 4300034374 | C25: ='📋 ORDERS'!F21 -> 15744967 | D25: ='📋 ORDERS'!G21 -> 24152 CC/W33 | E25: ='📋 ORDERS'!H21 -> BEARING 24152 CC/W33 SKF | F25: ='📋 ORDERS'!I21 -> 46113 | G25: 46275 | H25: ='📋 ORDERS'!L21 -> 3
... B142: ='📋 ORDERS'!E138 -> 4300037783 | C142: ='📋 ORDERS'!F138 -> 15153017 | D142: ='📋 ORDERS'!G138 -> 6316/C3 | E142: ='📋 ORDERS'!H138 -> BEARING 6316-C3;FRAME 250S/M;WEG | F142: ='📋 ORDERS'!I138 -> 46154 | G142: 46240 | H142: ='📋 ORDERS'!L138 -> 2

Sheet 📋 ORDERS
B1: 📦 TATA — ORDER DATA
B2: 🔵 AZUL=preencha 🟢 VERDE=automático 🟣 ROXO=entrega cliente ➕ Copie linha para novos pedidos
B3: Order Line | C3: SKF Order | D3: TATA Order | E3: Vulcan Order (PO) | F3: Material | G3: Designation | H3: Short Text | I3: Order Date | J3: Est. SKF Delivery Date | K3: Warehouse | L3: Qty Ordered | M3: Qty Shipped | N3: % Shipped | O3: Unit Price | P3: Line Total USD | Q3: Invoice No. | R3: Status | S3: Days to Delivery | T3: Month/Year | U3: Est. Customer Delivery Month | V3: Qty Pending | W3: Customer ID | X3: SKF Collection Date | Y3: ✔ Delivered to Customer | Z3: Customer Delivery Date | AA3: Notes
B4: 0003A | C4: 26Z0000099 | D4: 252911949 | E4: 4300034814 | F4: 15643491 | G4: HA 3128 | H4: BRG BUSHING ADAPTER 125.41MM HA 3128 SKF | I4: 46057 | J4: 46127 | K4: EMWH | L4: 4 | M4: 4 | N4: =IF(L4=0,0,M4/L4) -> 1 | O4: 113.78 | P4: =L4*O4 -> 455.12 | Q4: 12568 | R4: COLLECTED | S4: =IF(Y4="✔","✔ OK",IF(OR(J4="",J4=0),"TBA",INT(J4-I4))) -> ✔ OK | T4: =IF(I4="","",TEXT(MONTH(I4),"00")&"/"&YEAR(I4)) -> 02/2026 | U4: =IF(Y4="✔","OK",IF(OR(J4="",J4=0),"",TEXT(MONTH(J4+20),"00")&"/"&TEXT(YEAR(J4+20),"0000"))) -> OK | V4: =L4-M4 -> 0 | W4: F66050 | X4: 46163 | Y4: ✔ | Z4: 46181
B5: 0005A | C5: 26Z0000099 | D5: 252911949 | E5: 4300034814 | F5: 13040369 | G5: COP.ATL160M | H5: LABYRINTH SEAL 160MMATL TIMKEN | I5: 46057 | J5: 46155 | K5: EMWH | L5: 2 | M5: 2 | N5: =IF(L5=0,0,M5/L5) -> 1 | O5: 266.66 | P5: =L5*O5 -> 533.32 | Q5: 12611 | R5: COLLECTED | S5: =IF(Y5="✔","✔ OK",IF(OR(J5="",J5=0),"TBA",INT(J5-I5))) -> ✔ OK | T5: =IF(I5="","",TEXT(MONTH(I5),"00")&"/"&YEAR(I5)) -> 02/2026 | U5: =IF(Y5="✔","OK",IF(OR(J5="",J5=0),"",TEXT(MONTH(J5+20),"00")&"/"&TEXT(YEAR(J5+20),"0000"))) -> OK | V5: =L5-M5 -> 0 | W5: F66050 | X5: 46163 | Y5: ✔ | Z5: 46181
B6: 0006A | C6: 26Z0000099 | D6: 252911949 | E6: 4300034814 | F6: 15153568 | G6: COP.01EB180MGR | H6: BALL BRNG 01 B 180MM GR COOPER | I6: 46057 | J6: 46169 | K6: EMWH | L6: 2 | M6: 2 | N6: =IF(L6=0,0,M6/L6) -> 1 | O6: 2441.75 | P6: =L6*O6 -> 4883.5 | Q6: 12660 | R6: COLLECTED | S6: =IF(Y6="✔","✔ OK",IF(OR(J6="",J6=0),"TBA",INT(J6-I6))) -> ✔ OK | T6: =IF(I6="","",TEXT(MONTH(I6),"00")&"/"&YEAR(I6)) -> 02/2026 | U6: =IF(Y6="✔","OK",IF(OR(J6="",J6=0),"",TEXT(MONTH(J6+20),"00")&"/"&TEXT(YEAR(J6+20),"0000"))) -> OK | V6: =L6-M6 -> 0 | W6: F66050 | X6: 46163 | Y6: ✔ | Z6: 46184
B7: 0001A | C7: 26Z0000097 | D7: 252911950 | F7: 15002466 | G7: 6322/C3VL0241 | H7: DEEP GROOVE BALL BEARING - INSOCOAT 6322 | I7: 46056 | J7: 46155 | K7: EMWH | L7: 2 | M7: 2 | N7: =IF(L7=0,0,M7/L7) -> 1 | O7: 915.85 | P7: =L7*O7 -> 1831.7 | Q7: 12612 | R7: COLLECTED | S7: =IF(Y7="✔","✔ OK",IF(OR(J7="",J7=0),"TBA",INT(J7-I7))) -> 99 | T7: =IF(I7="","",TEXT(MONTH(I7),"00")&"/"&YEAR(I7)) -> 02/2026 | U7: =IF(Y7="✔","OK",IF(OR(J7="",J7=0),"",TEXT(MONTH(J7+20),"00")&"/"&TEXT(YEAR(J7+20),"0000"))) -> 06/2026 | V7: =L7-M7 -> 0 | W7: F66050 | X7: 46163 | Y7: ⚠ | AA7: Delivery on the 8.06.2026
B8: 0001A | C8: 25Z0002759 | D8: 252911760 | E8: 4300033496 | F8: 15501296 | G8: COP.01EB125MGR | H8: CYL ROLL BRG 01 B 125M GR COOPER | I8: 46014 | J8: 46085 | K8: EMWH | L8: 1 | M8: 1 | N8: =IF(L8=0,0,M8/L8) -> 1 | O8: 1048.88 | P8: =L8*O8 -> 1048.88 | Q8: 12403 | R8: COLLECTED | S8: =IF(Y8="✔","✔ OK",IF(OR(J8="",J8=0),"TBA",INT(J8-I8))) -> ✔ OK | T8: =IF(I8="","",TEXT(MONTH(I8),"00")&"/"&YEAR(I8)) -> 12/2025 | U8: =IF(Y8="✔","OK",IF(OR(J8="",J8=0),"",TEXT(MONTH(J8+20),"00")&"/"&TEXT(YEAR(J8+20),"0000"))) -> OK | V8: =L8-M8 -> 0 | W8: F66050 | X8: 46128 | Y8: ✔ | Z8: 46191
B9: 0005A | C9: 25Z0002759 | D9: 252911760 | E9: 4300033496 | F9: 13188279 | G9: COP.01EB180MGR | H9: CL RL BRG 01 B 180M GR COOPER BEARINGS | I9: 46014 | J9: 46120 | K9: EMWH | L9: 3 | M9: 3 | N9: =IF(L9=0,0,M9/L9) -> 1 | O9: 2441.75 | P9: =L9*O9 -> 7325.25 | Q9: 12452 | R9: COLLECTED | S9: =IF(Y9="✔","✔ OK",IF(OR(J9="",J9=0),"TBA",INT(J9-I9))) -> ✔ OK | T9: =IF(I9="","",TEXT(MONTH(I9),"00")&"/"&YEAR(I9)) -> 12/2025 | U9: =IF(Y9="✔","OK",IF(OR(J9="",J9=0),"",TEXT(MONTH(J9+20),"00")&"/"&TEXT(YEAR(J9+20),"0000"))) -> OK | V9: =L9-M9 -> 0 | W9: F66050 | X9: 46128 | Y9: ✔ | Z9: 46191
B10: 0001A | C10: 26Z0000402 | D10: 262910345 | F10: 13188470 | G10: COP.01EB140MGR | H10: CL RL BRG 01 B 140M GR COOPER BEARINGS | I10: 46161 | J10: 46246 | K10: EMWH | L10: 1 | M10: 1 | N10: =IF(L10=0,0,M10/L10) -> 1 | O10: 1437.72 | P10: =L10*O10 -> 1437.72 | Q10: 0000000 | R10: SHS | S10: =IF(Y10="✔","✔ OK",IF(OR(J10="",J10=0),"TBA",INT(J10-I10))) -> 85 | T10: =IF(I10="","",TEXT(MONTH(I10),"00")&"/"&YEAR(I10)) -> 05/2026 | U10: =IF(Y10="✔","OK",IF(OR(J10="",J10=0),"",TEXT(MONTH(J10+20),"00")&"/"&TEXT(YEAR(J10+20),"0000"))) -> 09/2026 | V10: =L10-M10 -> 0 | W10: F66050 | Y10: ✘ | AA10: Expected delivery at SKF July 7
B11: 0005A | C11: 26Z0000402 | D11: 262910345 | F11: 13040555 | G11: COP.02EB180MGR | H11: CL RL BRG 02 B 180M GR COOPER BEARINGS | I11: 46161 | J11: 46253 | K11: EMWH | L11: 5 | M11: 5 | N11: =IF(L11=0,0,M11/L11) -> 1 | O11: 4238.23 | P11: =L11*O11 -> 21191.15 | Q11: 0000000 | R11: RPI | S11: =IF(Y11="✔","✔ OK",IF(OR(J11="",J11=0),"TBA",INT(J11-I11))) -> 92 | T11: =IF(I11="","",TEXT(MONTH(I11),"00")&"/"&YEAR(I11)) -> 05/2026 | U11: =IF(Y11="✔","OK",IF(OR(J11="",J11=0),"",TEXT(MONTH(J11+20),"00")&"/"&TEXT(YEAR(J11+20),"0000"))) -> 09/2026 | V11: =L11-M11 -> 0 | W11: F66050 | Y11: ✘ | AA11: Expected delivery at SKF July 7
B12: 0006A | C12: 26Z0000402 | D12: 262910345 | F12: 13040555 | G12: COP.02EB180MGR | H12: CL RL BRG 02 B 180M GR COOPER BEARINGS | I12: 46161 | J12: 46253 | K12: EMWH | L12: 2 | M12: 2 | N12: =IF(L12=0,0,M12/L12) -> 1 | O12: 4238.23 | P12: =L12*O12 -> 8476.46 | Q12: 0000000 | R12: RPI | S12: =IF(Y12="✔","✔ OK",IF(OR(J12="",J12=0),"TBA",INT(J12-I12))) -> 92 | T12: =IF(I12="","",TEXT(MONTH(I12),"00")&"/"&YEAR(I12)) -> 05/2026 | U12: =IF(Y12="✔","OK",IF(OR(J12="",J12=0),"",TEXT(MONTH(J12+20),"00")&"/"&TEXT(YEAR(J12+20),"0000"))) -> 09/2026 | V12: =L12-M12 -> 0 | W12: F66050 | Y12: ✘ | AA12: Expected delivery at SKF July 7
B13: 0009A | C13: 26Z0000402 | D13: 262910345 | F13: 13188470 | G13: COP.01EB140MGR | H13: CL RL BRG 01 B 140M GR COOPER BEARINGS | I13: 46161 | J13: 46225 | K13: EMWH | L13: 1 | M13: 1 | N13: =IF(L13=0,0,M13/L13) -> 1 | O13: 1437.72 | P13: =L13*O13 -> 1437.72 | Q13: 0000000 | R13: SHS | S13: =IF(Y13="✔","✔ OK",IF(OR(J13="",J13=0),"TBA",INT(J13-I13))) -> 64 | T13: =IF(I13="","",TEXT(MONTH(I13),"00")&"/"&YEAR(I13)) -> 05/2026 | U13: =IF(Y13="✔","OK",IF(OR(J13="",J13=0),"",TEXT(MONTH(J13+20),"00")&"/"&TEXT(YEAR(J13+20),"0000"))) -> 08/2026 | V13: =L13-M13 -> 0 | W13: F66050 | Y13: ✘ | AA13: Expected delivery at SKF July 7
B14: 0002B | C14: 26Z0000382 | D14: 262910320 | E14: 4300037223 | F14: 15134397 | G14: SRV.NU 407 | H14: CYL ROL BEARING | I14: 46154 | J14: 46239 | K14: EMWH | L14: 3 | M14: 0 | N14: =IF(L14=0,0,M14/L14) -> 0 | O14: 71.7 | P14: =L14*O14 -> 215.1 | Q14: 0000000 | R14: SHS | S14: =IF(Y14="✔","✔ OK",IF(OR(J14="",J14=0),"TBA",INT(J14-I14))) -> 85 | T14: =IF(I14="","",TEXT(MONTH(I14),"00")&"/"&YEAR(I14)) -> 05/2026 | U14: =IF(Y14="✔","OK",IF(OR(J14="",J14=0),"",TEXT(MONTH(J14+20),"00")&"/"&TEXT(YEAR(J14+20),"0000"))) -> 08/2026 | V14: =L14-M14 -> 3 | W14: F66050 | Y14: ✘ | AA14: Requested from EDC dispatch date
B15: 0004A | C15: 26Z0000383 | D15: 262910319 | E15: 4300037815 | F15: 13040555 | G15: COP.02EB180MGR | H15: CYL ROLL BRG MSM180BR TIMKEN | I15: 46154 | J15: 46246 | K15: EMWH | L15: 2 | M15: 2 | N15: =IF(L15=0,0,M15/L15) -> 1 | O15: 4395.2 | P15: =L15*O15 -> 8790.4 | Q15: 0000000 | R15: SHS | S15: =IF(Y15="✔","✔ OK",IF(OR(J15="",J15=0),"TBA",INT(J15-I15))) -> 92 | T15: =IF(I15="","",TEXT(MONTH(I15),"00")&"/"&YEAR(I15)) -> 05/2026 | U15: =IF(Y15="✔","OK",IF(OR(J15="",J15=0),"",TEXT(MONTH(J15+20),"00")&"/"&TEXT(YEAR(J15+20),"0000"))) -> 09/2026 | V15: =L15-M15 -> 0 | W15: F66050 | Y15: ✘ | AA15: Requested for improved production
B16: 0005A | C16: 26Z0000383 | D16: 262910319 | E16: 4300037815 | F16: 13040485 | G16: COP.02EB220MGR | H16: CYL ROLL BRG MSM220BR TIMKEN | I16: 46154 | J16: 46246 | K16: EMWH | L16: 1 | M16: 1 | N16: =IF(L16=0,0,M16/L16) -> 1 | O16: 10786.44 | P16: =L16*O16 -> 10786.44 | Q16: 0000000 | R16: SHS | S16: =IF(Y16="✔","✔ OK",IF(OR(J16="",J16=0),"TBA",INT(J16-I16))) -> 92 | T16: =IF(I16="","",TEXT(MONTH(I16),"00")&"/"&YEAR(I16)) -> 05/2026 | U16: =IF(Y16="✔","OK",IF(OR(J16="",J16=0),"",TEXT(MONTH(J16+20),"00")&"/"&TEXT(YEAR(J16+20),"0000"))) -> 09/2026 | V16: =L16-M16 -> 0 | W16: F66050 | Y16: ✘ | AA16: Requested for improved production
B17: 0006A | C17: 26Z0000383 | D17: 262910319 | E17: 4300037815 | F17: 13040555 | G17: COP.02EB180MGR | H17: CYL ROLL BRG MSM180BR TIMKEN | I17: 46154 | J17: 46246 | K17: EMWH | L17: 7 | M17: 7 | N17: =IF(L17=0,0,M17/L17) -> 1 | O17: 4395.2 | P17: =L17*O17 -> 30766.4 | Q17: 0000000 | R17: SHS | S17: =IF(Y17="✔","✔ OK",IF(OR(J17="",J17=0),"TBA",INT(J17-I17))) -> 92 | T17: =IF(I17="","",TEXT(MONTH(I17),"00")&"/"&YEAR(I17)) -> 05/2026 | U17: =IF(Y17="✔","OK",IF(OR(J17="",J17=0),"",TEXT(MONTH(J17+20),"00")&"/"&TEXT(YEAR(J17+20),"0000"))) -> 09/2026 | V17: =L17-M17 -> 0 | W17: F66050 | Y17: ✘ | AA17: Requested for improved production
B18: 0007A | C18: 26Z0000383 | D18: 262910319 | E18: 4300037815 | F18: 15509234 | G18: 70X110X10 HMSA10 RG | H18: LIP SEAL FKM 70MM 110MM | I18: 46154 | J18: 46239 | K18: EMWH | L18: 12 | M18: 12 | N18: =IF(L18=0,0,M18/L18) -> 1 | O18: 2.71 | P18: =L18*O18 -> 32.52 | Q18: 0000000 | R18: SHS | S18: =IF(Y18="✔","✔ OK",IF(OR(J18="",J18=0),"TBA",INT(J18-I18))) -> 85 | T18: =IF(I18="","",TEXT(MONTH(I18),"00")&"/"&YEAR(I18)) -> 05/2026 | U18: =IF(Y18="✔","OK",IF(OR(J18="",J18=0),"",TEXT(MONTH(J18+20),"00")&"/"&TEXT(YEAR(J18+20),"0000"))) -> 08/2026 | V18: =L18-M18 -> 0 | W18: F66050 | Y18: ✘ | AA18: 25.06.2026 ETA - SANR0409719
B19: 0002A | C19: 26Z0000279 | D19: 252912134 | E19: 4300034374 | F19: 15744967 | G19: 24152 CC/W33 | H19: BEARING 24152 CC/W33 SKF | I19: 46113 | J19: 46225 | K19: EMWH | L19: 5 | M19: 0 | N19: =IF(L19=0,0,M19/L19) -> 0 | O19: 2589.33 | P19: =L19*O19 -> 12946.65 | Q19: 0000000 | R19: RPI | S19: =IF(Y19="✔","✔ OK",IF(OR(J19="",J19=0),"TBA",INT(J19-I19))) -> 112 | T19: =IF(I19="","",TEXT(MONTH(I19),"00")&"/"&YEAR(I19)) -> 04/2026 | U19: =IF(Y19="✔","OK",IF(OR(J19="",J19=0),"",TEXT(MONTH(J19+20),"00")&"/"&TEXT(YEAR(J19+20),"0000"))) -> 08/2026 | V19: =L19-M19 -> 5 | W19: F66050 | X19: 46176 | Y19: 🔮 | AA19: Request to order directly from factory - Cephas to change order
B20: 0002B | C20: 26Z0000279 | D20: 252912134 | E20: 4300034374 | F20: 15744967 | G20: 24152 CC/W33 | H20: BEARING 24152 CC/W33 SKF | I20: 46113 | J20: 46225 | K20: EMWH | L20: 4 | M20: 0 | N20: =IF(L20=0,0,M20/L20) -> 0 | O20: 2589.33 | P20: =L20*O20 -> 10357.32 | Q20: 0000000 | R20: RPI | S20: =IF(Y20="✔","✔ OK",IF(OR(J20="",J20=0),"TBA",INT(J20-I20))) -> 112 | T20: =IF(I20="","",TEXT(MONTH(I20),"00")&"/"&YEAR(I20)) -> 04/2026 | U20: =IF(Y20="✔","OK",IF(OR(J20="",J20=0),"",TEXT(MONTH(J20+20),"00")&"/"&TEXT(YEAR(J20+20),"0000"))) -> 08/2026 | V20: =L20-M20 -> 4 | W20: F66050 | X20: 46176 | Y20: 🔮 | AA20: Request to order directly from factory - Cephas to change order
B21: 0002C | C21: 26Z0000279 | D21: 252912134 | E21: 4300034374 | F21: 15744967 | G21: 24152 CC/W33 | H21: BEARING 24152 CC/W33 SKF | I21: 46113 | J21: 46225 | K21: EMWH | L21: 3 | M21: 0 | N21: =IF(L21=0,0,M21/L21) -> 0 | O21: 2589.33 | P21: =L21*O21 -> 7767.99 | Q21: 0000000 | R21: RPI | S21: =IF(Y21="✔","✔ OK",IF(OR(J21="",J21=0),"TBA",INT(J21-I21))) -> 112 | T21: =IF(I21="","",TEXT(MONTH(I21),"00")&"/"&YEAR(I21)) -> 04/2026 | U21: =IF(Y21="✔","OK",IF(OR(J21="",J21=0),"",TEXT(MONTH(J21+20),"00")&"/"&TEXT(YEAR(J21+20),"0000"))) -> 08/2026 | V21: =L21-M21 -> 3 | W21: F66050 | X21: 46176 | Y21: 🔮 | AA21: Request to order directly from factory - Cephas to change order
B22: 0007A | C22: 26Z0000279 | D22: 252912134 | E22: 4300034374 | F22: 15744967 | G22: 24152 CC/W33 | H22: BEARING 24152 CC/W33 SKF | I22: 46113 | J22: 46225 | K22: EMWH | L22: 2 | M22: 0 | N22: =IF(L22=0,0,M22/L22) -> 0 | O22: 2589.33 | P22: =L22*O22 -> 5178.66 | Q22: 0000000 | R22: RPI | S22: =IF(Y22="✔","✔ OK",IF(OR(J22="",J22=0),"TBA",INT(J22-I22))) -> 112 | T22: =IF(I22="","",TEXT(MONTH(I22),"00")&"/"&YEAR(I22)) -> 04/2026 | U22: =IF(Y22="✔","OK",IF(OR(J22="",J22=0),"",TEXT(MONTH(J22+20),"00")&"/"&TEXT(YEAR(J22+20),"0000"))) -> 08/2026 | V22: =L22-M22 -> 2 | W22: F66050 | X22: 46176 | Y22: 🔮 | AA22: Request to order directly from factory - Cephas to change order
B23: 0002C | C23: 26Z0000280 | D23: 262910001 | E23: 4300036757 | F23: 15475312 | G23: CMPT 2310TX20 | H23: SENSOR INTEGRATED CABLE; CMPT 2310TX20 | I23: 46113 | J23: 46205 | K23: EMWH | L23: 7 | M23: 7 | N23: =IF(L23=0,0,M23/L23) -> 1 | O23: 495 | P23: =L23*O23 -> 3465 | Q23: 0000000 | R23: SHS | S23: =IF(Y23="✔","✔ OK",IF(OR(J23="",J23=0),"TBA",INT(J23-I23))) -> 92 | T23: =IF(I23="","",TEXT(MONTH(I23),"00")&"/"&YEAR(I23)) -> 04/2026 | U23: =IF(Y23="✔","OK",IF(OR(J23="",J23=0),"",TEXT(MONTH(J23+20),"00")&"/"&TEXT(YEAR(J23+20),"0000"))) -> 07/2026 | V23: =L23-M23 -> 0 | W23: F66050 | Y23: 🔮 | AA23: Requested for production improvement , no global availability
B24: 0003A | C24: 26Z0000280 | D24: 262910001 | E24: 4300036757 | F24: 15475312 | G24: CMPT 2310TX20 | H24: SENSOR INTEGRATED CABLE; CMPT 2310TX20 | I24: 46113 | J24: 46205 | K24: EMWH | L24: 13 | M24: 13 | N24: =IF(L24=0,0,M24/L24) -> 1 | O24: 495 | P24: =L24*O24 -> 6435 | Q24: 0000000 | R24: SHS | S24: =IF(Y24="✔","✔ OK",IF(OR(J24="",J24=0),"TBA",INT(J24-I24))) -> 92 | T24: =IF(I24="","",TEXT(MONTH(I24),"00")&"/"&YEAR(I24)) -> 04/2026 | U24: =IF(Y24="✔","OK",IF(OR(J24="",J24=0),"",TEXT(MONTH(J24+20),"00")&"/"&TEXT(YEAR(J24+20),"0000"))) -> 07/2026 | V24: =L24-M24 -> 0 | W24: F66050 | Y24: 🔮 | AA24: Requested for production improvement , no global availability
B25: 0002B | C25: 26Z0000240 | D25: 252912296 | E25: 4300036353 | F25: 13117942 | G25: PHF TB4545X65MM | H25: LCKG BUSH 65MM | I25: 46100 | J25: 46344 | K25: EMWH | L25: 4 | M25: 4 | N25: =IF(L25=0,0,M25/L25) -> 1 | O25: 60.21 | P25: =L25*O25 -> 240.84 | Q25: 0000000 | R25: RBK | S25: =IF(Y25="✔","✔ OK",IF(OR(J25="",J25=0),"TBA",INT(J25-I25))) -> 244 | T25: =IF(I25="","",TEXT(MONTH(I25),"00")&"/"&YEAR(I25)) -> 03/2026 | U25: =IF(Y25="✔","OK",IF(OR(J25="",J25=0),"",TEXT(MONTH(J25+20),"00")&"/"&TEXT(YEAR(J25+20),"0000"))) -> 12/2026 | V25: =L25-M25 -> 0 | W25: F66050 | Y25: ✘ | AA25: Awaiting improvement from Factory
B26: 0001A | C26: 26Z0000428 | D26: 262910449 | E26: 4300038759 | F26: 15647107 | G26: ASNH 526 | H26: SIDE COVER ASNH 526 SKF | I26: 46169 | J26: 46175 | K26: QZSS | L26: 2 | M26: 2 | N26: =IF(L26=0,0,M26/L26) -> 1 | O26: 5.54 | P26: =L26*O26 -> 11.08 | Q26: 12765 | R26: READY FOR COLLECTION | S26: =IF(Y26="✔","✔ OK",IF(OR(J26="",J26=0),"TBA",INT(J26-I26))) -> 6 | T26: =IF(I26="","",TEXT(MONTH(I26),"00")&"/"&YEAR(I26)) -> 05/2026 | U26: =IF(Y26="✔","OK",IF(OR(J26="",J26=0),"",TEXT(MONTH(J26+20),"00")&"/"&TEXT(YEAR(J26+20),"0000"))) -> 06/2026 | V26: =L26-M26 -> 0 | W26: F66050 | Y26: 🔮 | AA26: 2026-06-09 - SKF informed that it is available for collection.
B27: 0002A | C27: 26Z0000428 | D27: 262910449 | E27: 4300038759 | F27: 15647107 | G27: ASNH 526 | H27: SIDE COVER ASNH 526 SKF | I27: 46169 | J27: 46175 | K27: QZSS | L27: 2 | M27: 2 | N27: =IF(L27=0,0,M27/L27) -> 1 | O27: 5.54 | P27: =L27*O27 -> 11.08 | Q27: 12765 | R27: READY FOR COLLECTION | S27: =IF(Y27="✔","✔ OK",IF(OR(J27="",J27=0),"TBA",INT(J27-I27))) -> 6 | T27: =IF(I27="","",TEXT(MONTH(I27),"00")&"/"&YEAR(I27)) -> 05/2026 | U27: =IF(Y27="✔","OK",IF(OR(J27="",J27=0),"",TEXT(MONTH(J27+20),"00")&"/"&TEXT(YEAR(J27+20),"0000"))) -> 06/2026 | V27: =L27-M27 -> 0 | W27: F66050 | Y27: 🔮 | AA27: 2026-06-09 - SKF informed that it is available for collection.
B28: 0006A | C28: 26Z0000428 | D28: 262910449 | E28: 4300038759 | F28: 15056552 | G28: OH 3152 H | H28: ADAPTER SLEEVE;OH 3152 H;SKF | I28: 46169 | J28: 46175 | K28: QZSS | L28: 1 | M28: 1 | N28: =IF(L28=0,0,M28/L28) -> 1 | O28: 601.87 | P28: =L28*O28 -> 601.87 | Q28: 12765 | R28: READY FOR COLLECTION | S28: =IF(Y28="✔","✔ OK",IF(OR(J28="",J28=0),"TBA",INT(J28-I28))) -> 6 | T28: =IF(I28="","",TEXT(MONTH(I28),"00")&"/"&YEAR(I28)) -> 05/2026 | U28: =IF(Y28="✔","OK",IF(OR(J28="",J28=0),"",TEXT(MONTH(J28+20),"00")&"/"&TEXT(YEAR(J28+20),"0000"))) -> 06/2026 | V28: =L28-M28 -> 0 | W28: F66050 | Y28: 🔮 | AA28: 2026-06-09 - SKF informed that it is available for collection.
B29: 0008A | C29: 26Z0000428 | D29: 262910449 | E29: 4300038759 | F29: 15388676 | G29: 22316 E/C3 | H29: BEARING 22316 E C3 SKF | I29: 46169 | J29: 46175 | K29: QZSS | L29: 1 | M29: 1 | N29: =IF(L29=0,0,M29/L29) -> 1 | O29: 146.04 | P29: =L29*O29 -> 146.04 | Q29: 12765 | R29: READY FOR COLLECTION | S29: =IF(Y29="✔","✔ OK",IF(OR(J29="",J29=0),"TBA",INT(J29-I29))) -> 6 | T29: =IF(I29="","",TEXT(MONTH(I29),"00")&"/"&YEAR(I29)) -> 05/2026 | U29: =IF(Y29="✔","OK",IF(OR(J29="",J29=0),"",TEXT(MONTH(J29+20),"00")&"/"&TEXT(YEAR(J29+20),"0000"))) -> 06/2026 | V29: =L29-M29 -> 0 | W29: F66050 | Y29: 🔮 | AA29: 2026-06-09 - SKF informed that it is available for collection.
B30: 0009A | C30: 26Z0000428 | D30: 262910449 | E30: 4300038759 | F30: 15062473 | G30: H 318 | H30: ADAPTER SLEEVE H 318 SKF | I30: 46169 | J30: 46175 | K30: QZSS | L30: 3 | M30: 3 | N30: =IF(L30=0,0,M30/L30) -> 1 | O30: 31.31 | P30: =L30*O30 -> 93.93 | Q30: 12765 | R30: READY FOR COLLECTION | S30: =IF(Y30="✔","✔ OK",IF(OR(J30="",J30=0),"TBA",INT(J30-I30))) -> 6 | T30: =IF(I30="","",TEXT(MONTH(I30),"00")&"/"&YEAR(I30)) -> 05/2026 | U30: =IF(Y30="✔","OK",IF(OR(J30="",J30=0),"",TEXT(MONTH(J30+20),"00")&"/"&TEXT(YEAR(J30+20),"0000"))) -> 06/2026 | V30: =L30-M30 -> 0 | W30: F66050 | Y30: 🔮 | AA30: 2026-06-09 - SKF informed that it is available for collection.
B31: 0010A | C31: 26Z0000428 | D31: 262910449 | E31: 4300038759 | F31: 15647107 | G31: ASNH 526 | H31: SIDE COVER ASNH 526 SKF | I31: 46169 | J31: 46175 | K31: QZSS | L31: 1 | M31: 1 | N31: =IF(L31=0,0,M31/L31) -> 1 | O31: 5.54 | P31: =L31*O31 -> 5.54 | Q31: 12765 | R31: READY FOR COLLECTION | S31: =IF(Y31="✔","✔ OK",IF(OR(J31="",J31=0),"TBA",INT(J31-I31))) -> 6 | T31: =IF(I31="","",TEXT(MONTH(I31),"00")&"/"&YEAR(I31)) -> 05/2026 | U31: =IF(Y31="✔","OK",IF(OR(J31="",J31=0),"",TEXT(MONTH(J31+20),"00")&"/"&TEXT(YEAR(J31+20),"0000"))) -> 06/2026 | V31: =L31-M31 -> 0 | W31: F66050 | Y31: 🔮 | AA31: 2026-06-09 - SKF informed that it is available for collection.
B32: 0011A | C32: 26Z0000126 | D32: 252911981 | E32: 4300035325 | F32: 15149626 | G32: TU 50 TF | H32: BEARING UNIT NON-LOC PASS SPLIT PED | I32: 46066 | J32: 46134 | K32: EMWH | L32: 30 | M32: 30 | N32: =IF(L32=0,0,M32/L32) -> 1 | O32: 39.33 | P32: =L32*O32 -> 1179.9 | Q32: 12545 | R32: COLLECTED | S32: =IF(Y32="✔","✔ OK",IF(OR(J32="",J32=0),"TBA",INT(J32-I32))) -> 68 | T32: =IF(I32="","",TEXT(MONTH(I32),"00")&"/"&YEAR(I32)) -> 02/2026 | U32: =IF(Y32="✔","OK",IF(OR(J32="",J32=0),"",TEXT(MONTH(J32+20),"00")&"/"&TEXT(YEAR(J32+20),"0000"))) -> 05/2026 | V32: =L32-M32 -> 0 | W32: F66050 | X32: 46132 | Y32: ⚠ | AA32: Gate Pass Issue (Still it is in TATA Stock)
B33: 0013A | C33: 26Z0000126 | D33: 252911981 | E33: 4300035325 | F33: 15055683 | G33: 22240 CC/W33 | H33: BEARING 22240 CC/W33 SKF | I33: 46066 | J33: 46148 | K33: EMWH | L33: 1 | M33: 1 | N33: =IF(L33=0,0,M33/L33) -> 1 | O33: 1044.34 | P33: =L33*O33 -> 1044.34 | Q33: 12632 | R33: COLLECTED | S33: =IF(Y33="✔","✔ OK",IF(OR(J33="",J33=0),"TBA",INT(J33-I33))) -> 82 | T33: =IF(I33="","",TEXT(MONTH(I33),"00")&"/"&YEAR(I33)) -> 02/2026 | U33: =IF(Y33="✔","OK",IF(OR(J33="",J33=0),"",TEXT(MONTH(J33+20),"00")&"/"&TEXT(YEAR(J33+20),"0000"))) -> 05/2026 | V33: =L33-M33 -> 0 | W33: F66050 | X33: 46163 | Y33: ⚠ | AA33: Delivery on the 8.06.2026
B34: 0014A | C34: 26Z0000126 | D34: 252911981 | E34: 4300035325 | F34: 15375665 | G34: SNL 518-615 | H34: PILLOW BLOCK NOD CI 80MM SNL 518-615 SKF | I34: 46066 | J34: 46197 | K34: EMWH | L34: 5 | M34: 5 | N34: =IF(L34=0,0,M34/L34) -> 1 | O34: 110.25 | P34: =L34*O34 -> 551.25 | Q34: 12723 | R34: READY FOR COLLECTION | S34: =IF(Y34="✔","✔ OK",IF(OR(J34="",J34=0),"TBA",INT(J34-I34))) -> 131 | T34: =IF(I34="","",TEXT(MONTH(I34),"00")&"/"&YEAR(I34)) -> 02/2026 | U34: =IF(Y34="✔","OK",IF(OR(J34="",J34=0),"",TEXT(MONTH(J34+20),"00")&"/"&TEXT(YEAR(J34+20),"0000"))) -> 07/2026 | V34: =L34-M34 -> 0 | W34: F66050 | X34: 46175 | Y34: 🔮
B35: 0015A | C35: 26Z0000126 | D35: 252911981 | E35: 4300035325 | F35: 15351089 | G35: 22218 EK | H35: SPHERICAL ROLLER BEARING 22218 EK | I35: 46066 | J35: 46197 | K35: EMWH | L35: 5 | M35: 5 | N35: =IF(L35=0,0,M35/L35) -> 1 | O35: 108.14 | P35: =L35*O35 -> 540.7 | Q35: 12723 | R35: READY FOR COLLECTION | S35: =IF(Y35="✔","✔ OK",IF(OR(J35="",J35=0),"TBA",INT(J35-I35))) -> 131 | T35: =IF(I35="","",TEXT(MONTH(I35),"00")&"/"&YEAR(I35)) -> 02/2026 | U35: =IF(Y35="✔","OK",IF(OR(J35="",J35=0),"",TEXT(MONTH(J35+20),"00")&"/"&TEXT(YEAR(J35+20),"0000"))) -> 07/2026 | V35: =L35-M35 -> 0 | W35: F66050 | X35: 46175 | Y35: 🔮
B36: 0016A | C36: 26Z0000126 | D36: 252911981 | E36: 4300035325 | G36: H 318 | H36: ADAPTER SLEEVE H 318 SKF | I36: 46066 | J36: 46197 | K36: EMWH | L36: 5 | M36: 5 | N36: =IF(L36=0,0,M36/L36) -> 1 | O36: 25.74 | P36: =L36*O36 -> 128.7 | Q36: 12723 | R36: READY FOR COLLECTION | S36: =IF(Y36="✔","✔ OK",IF(OR(J36="",J36=0),"TBA",INT(J36-I36))) -> 131 | T36: =IF(I36="","",TEXT(MONTH(I36),"00")&"/"&YEAR(I36)) -> 02/2026 | U36: =IF(Y36="✔","OK",IF(OR(J36="",J36=0),"",TEXT(MONTH(J36+20),"00")&"/"&TEXT(YEAR(J36+20),"0000"))) -> 07/2026 | V36: =L36-M36 -> 0 | W36: F66050 | X36: 46175 | Y36: 🔮
B37: 0017A | C37: 26Z0000126 | D37: 252911981 | E37: 4300035325 | F37: 13061642 | G37: TXL 518 | H37: SEAL TSN518 TK SKF | I37: 46066 | J37: 46197 | K37: EMWH | L37: 5 | M37: 5 | N37: =IF(L37=0,0,M37/L37) -> 1 | O37: 4.79 | P37: =L37*O37 -> 23.95 | Q37: 12723 | R37: READY FOR COLLECTION | S37: =IF(Y37="✔","✔ OK",IF(OR(J37="",J37=0),"TBA",INT(J37-I37))) -> 131 | T37: =IF(I37="","",TEXT(MONTH(I37),"00")&"/"&YEAR(I37)) -> 02/2026 | U37: =IF(Y37="✔","OK",IF(OR(J37="",J37=0),"",TEXT(MONTH(J37+20),"00")&"/"&TEXT(YEAR(J37+20),"0000"))) -> 07/2026 | V37: =L37-M37 -> 0 | W37: F66050 | X37: 46175 | Y37: 🔮
B38: 0018A | C38: 26Z0000126 | D38: 252911981 | E38: 4300035325 | F38: 13065456 | G38: FRB 12.5/160 | H38: LOCATING RING FRB 12.5/160 | I38: 46066 | J38: 46197 | K38: EMWH | L38: 10 | M38: 10 | N38: =IF(L38=0,0,M38/L38) -> 1 | O38: 3.35 | P38: =L38*O38 -> 33.5 | Q38: 12723 | R38: READY FOR COLLECTION | S38: =IF(Y38="✔","✔ OK",IF(OR(J38="",J38=0),"TBA",INT(J38-I38))) -> 131 | T38: =IF(I38="","",TEXT(MONTH(I38),"00")&"/"&YEAR(I38)) -> 02/2026 | U38: =IF(Y38="✔","OK",IF(OR(J38="",J38=0),"",TEXT(MONTH(J38+20),"00")&"/"&TEXT(YEAR(J38+20),"0000"))) -> 07/2026 | V38: =L38-M38 -> 0 | W38: F66050 | X38: 46175 | Y38: 🔮
B39: 0002A | C39: 26Z0000099 | D39: 252911949 | E39: 4300034814 | F39: 15375351 | G39: 30230 | H39: ROLL BEARING 30230 A FAG | I39: 46057 | J39: 46127 | K39: EMWH | L39: 4 | M39: 4 | N39: =IF(L39=0,0,M39/L39) -> 1 | O39: 419.07 | P39: =L39*O39 -> 1676.28 | Q39: 12568 | R39: COLLECTED | S39: =IF(Y39="✔","✔ OK",IF(OR(J39="",J39=0),"TBA",INT(J39-I39))) -> ✔ OK | T39: =IF(I39="","",TEXT(MONTH(I39),"00")&"/"&YEAR(I39)) -> 02/2026 | U39: =IF(Y39="✔","OK",IF(OR(J39="",J39=0),"",TEXT(MONTH(J39+20),"00")&"/"&TEXT(YEAR(J39+20),"0000"))) -> OK | V39: =L39-M39 -> 0 | W39: F66050 | X39: 46163 | Y39: ✔ | Z39: 46181
B40: 0004A | C40: 26Z0000126 | D40: 252911981 | E40: 4300035325 | F40: 15062560 | G40: 23056 CCK/W33 | H40: BEARING 23056 CCK/W33 SKF | I40: 46066 | J40: 46134 | K40: EMWH | L40: 1 | M40: 1 | N40: =IF(L40=0,0,M40/L40) -> 1 | O40: 1455.7 | P40: =L40*O40 -> 1455.7 | Q40: 12545 | R40: COLLECTED | S40: =IF(Y40="✔","✔ OK",IF(OR(J40="",J40=0),"TBA",INT(J40-I40))) -> 68 | T40: =IF(I40="","",TEXT(MONTH(I40),"00")&"/"&YEAR(I40)) -> 02/2026 | U40: =IF(Y40="✔","OK",IF(OR(J40="",J40=0),"",TEXT(MONTH(J40+20),"00")&"/"&TEXT(YEAR(J40+20),"0000"))) -> 05/2026 | V40: =L40-M40 -> 0 | W40: F66050 | X40: 46132 | Y40: ⚠ | AA40: Gate Pass Issue (Still it is in TATA Stock)
...

Sheet 🔍 LOOKUP
A1: 🔍 QUICK ORDER LOOKUP
B3: SEARCH TYPE | C3: ← CODE / NUMBER (Type here)
B4: SKF Order | C4: 26Z0000386 | K4: =IF($C$4="","",IFERROR(VALUE($C$4),$C$4)) -> 26Z0000386
B6: 📋 ORDER IDENTIFICATION
B7: Line | C7: SKF Order | D7: TATA Order | E7: Vulcan PO | F7: Warehouse | G7: Order Date | H7: SKF Delivery Date | I7: Days
B8: =IFERROR(INDEX('📋 ORDERS'!$B$4:$B$675,MATCH($K$4,IF($B$4="SKF Order",'📋 ORDERS'!$C$4:$C$675,IF($B$4="TATA Order",'📋 ORDERS'!$D$4:$D$675,IF($B$4="Vulcan PO",'📋 ORDERS'!$E$4:$E$675,'📋 ORDERS'!$Q$4:$Q$675))),0)),"") -> 0001A | C8: =IFERROR(INDEX('📋 ORDERS'!$C$4:$C$675,MATCH($K$4,IF($B$4="SKF Order",'📋 ORDERS'!$C$4:$C$675,IF($B$4="TATA Order",'📋 ORDERS'!$D$4:$D$675,IF($B$4="Vulcan PO",'📋 ORDERS'!$E$4:$E$675,'📋 ORDERS'!$Q$4:$Q$675))),0)),"") -> 26Z0000386 | D8: =IFERROR(INDEX('📋 ORDERS'!$D$4:$D$675,MATCH($K$4,IF($B$4="SKF Order",'📋 ORDERS'!$C$4:$C$675,IF($B$4="TATA Order",'📋 ORDERS'!$D$4:$D$675,IF($B$4="Vulcan PO",'📋 ORDERS'!$E$4:$E$675,'📋 ORDERS'!$Q$4:$Q$675))),0)),"") -> 262910319A | E8: =IFERROR(INDEX('📋 ORDERS'!$E$4:$E$675,MATCH($K$4,IF($B$4="SKF Order",'📋 ORDERS'!$C$4:$C$675,IF($B$4="TATA Order",'📋 ORDERS'!$D$4:$D$675,IF($B$4="Vulcan PO",'📋 ORDERS'!$E$4:$E$675,'📋 ORDERS'!$Q$4:$Q$675))),0)),"") -> 4300037815 | F8: =IFERROR(INDEX('📋 ORDERS'!$K$4:$K$675,MATCH($K$4,IF($B$4="SKF Order",'📋 ORDERS'!$C$4:$C$675,IF($B$4="TATA Order",'📋 ORDERS'!$D$4:$D$675,IF($B$4="Vulcan PO",'📋 ORDERS'!$E$4:$E$675,'📋 ORDERS'!$Q$4:$Q$675))),0)),"") -> EMWH | G8: =IFERROR(INDEX('📋 ORDERS'!$I$4:$I$675,MATCH($K$4,IF($B$4="SKF Order",'📋 ORDERS'!$C$4:$C$675,IF($B$4="TATA Order",'📋 ORDERS'!$D$4:$D$675,IF($B$4="Vulcan PO",'📋 ORDERS'!$E$4:$E$675,'📋 ORDERS'!$Q$4:$Q$675))),0)),"") -> 46155 | H8: =IFERROR(INDEX('📋 ORDERS'!$J$4:$J$675,MATCH($K$4,IF($B$4="SKF Order",'📋 ORDERS'!$C$4:$C$675,IF($B$4="TATA Order",'📋 ORDERS'!$D$4:$D$675,IF($B$4="Vulcan PO",'📋 ORDERS'!$E$4:$E$675,'📋 ORDERS'!$Q$4:$Q$675))),0)),"") -> 46182 | I8: =IFERROR(INDEX('📋 ORDERS'!$S$4:$S$675,MATCH($K$4,IF($B$4="SKF Order",'📋 ORDERS'!$C$4:$C$675,IF($B$4="TATA Order",'📋 ORDERS'!$D$4:$D$675,IF($B$4="Vulcan PO",'📋 ORDERS'!$E$4:$E$675,'📋 ORDERS'!$Q$4:$Q$675))),0)),"") -> ✔ OK
B10: Invoice No. | C10: Status | D10: Month/Year | E10: Unit Price | F10: Qty Ordered | G10: Qty Shipped | H10: Qty Pending | I10: SKF Designation
B11: =IFERROR(INDEX('📋 ORDERS'!$Q$4:$Q$675,MATCH($K$4,IF($B$4="SKF Order",'📋 ORDERS'!$C$4:$C$675,IF($B$4="TATA Order",'📋 ORDERS'!$D$4:$D$675,IF($B$4="Vulcan PO",'📋 ORDERS'!$E$4:$E$675,'📋 ORDERS'!$Q$4:$Q$675))),0)),"") -> 12675 | C11: =IFERROR(INDEX('📋 ORDERS'!$R$4:$R$675,MATCH($K$4,IF($B$4="SKF Order",'📋 ORDERS'!$C$4:$C$675,IF($B$4="TATA Order",'📋 ORDERS'!$D$4:$D$675,IF($B$4="Vulcan PO",'📋 ORDERS'!$E$4:$E$675,'📋 ORDERS'!$Q$4:$Q$675))),0)),"") -> COLLECTED | D11: =IFERROR(INDEX('📋 ORDERS'!$T$4:$T$675,MATCH($K$4,IF($B$4="SKF Order",'📋 ORDERS'!$C$4:$C$675,IF($B$4="TATA Order",'📋 ORDERS'!$D$4:$D$675,IF($B$4="Vulcan PO",'📋 ORDERS'!$E$4:$E$675,'📋 ORDERS'!$Q$4:$Q$675))),0)),"") -> 05/2026 | E11: =IFERROR(INDEX('📋 ORDERS'!$O$4:$O$675,MATCH($K$4,IF($B$4="SKF Order",'📋 ORDERS'!$C$4:$C$675,IF($B$4="TATA Order",'📋 ORDERS'!$D$4:$D$675,IF($B$4="Vulcan PO",'📋 ORDERS'!$E$4:$E$675,'📋 ORDERS'!$Q$4:$Q$675))),0)),"") -> 678.04 | F11: =IFERROR(INDEX('📋 ORDERS'!$L$4:$L$675,MATCH($K$4,IF($B$4="SKF Order",'📋 ORDERS'!$C$4:$C$675,IF($B$4="TATA Order",'📋 ORDERS'!$D$4:$D$675,IF($B$4="Vulcan PO",'📋 ORDERS'!$E$4:$E$675,'📋 ORDERS'!$Q$4:$Q$675))),0)),"") -> 20 | G11: =IFERROR(INDEX('📋 ORDERS'!$M$4:$M$675,MATCH($K$4,IF($B$4="SKF Order",'📋 ORDERS'!$C$4:$C$675,IF($B$4="TATA Order",'📋 ORDERS'!$D$4:$D$675,IF($B$4="Vulcan PO",'📋 ORDERS'!$E$4:$E$675,'📋 ORDERS'!$Q$4:$Q$675))),0)),"") -> 20 | H11: =IFERROR(INDEX('📋 ORDERS'!$U$4:$U$675,MATCH($K$4,IF($B$4="SKF Order",'📋 ORDERS'!$C$4:$C$675,IF($B$4="TATA Order",'📋 ORDERS'!$D$4:$D$675,IF($B$4="Vulcan PO",'📋 ORDERS'!$E$4:$E$675,'📋 ORDERS'!$Q$4:$Q$675))),0)),"") -> OK | I11: =IFERROR(INDEX('📋 ORDERS'!$G$4:$G$675,MATCH($K$4,IF($B$4="SKF Order",'📋 ORDERS'!$C$4:$C$675,IF($B$4="TATA Order",'📋 ORDERS'!$D$4:$D$675,IF($B$4="Vulcan PO",'📋 ORDERS'!$E$4:$E$675,'📋 ORDERS'!$Q$4:$Q$675))),0)),"") -> 22326 CCJA/W33VA405
B12: =IFERROR(REPT("█",ROUND((IFERROR(INDEX('📋 ORDERS'!$N$4:$N$675,MATCH($K$4,IF($B$4="SKF Order",'📋 ORDERS'!$C$4:$C$675,IF($B$4="TATA Order",'📋 ORDERS'!$D$4:$D$675,IF($B$4="Vulcan PO",'📋 ORDERS'!$E$4:$E$675,'📋 ORDERS'!$Q$4:$Q$675))),0)),0))*30,0))&REPT("░",30-ROUND((IFERROR(INDEX('📋 ORDERS'!$N$4:$N$675,MATCH($K$4,IF($B$4="SKF Order",'📋 ORDERS'!$C$4:$C$675,IF($B$4="TATA Order",'📋 ORDERS'!$D$4:$D$675,IF($B$4="Vulcan PO",'📋 ORDERS'!$E$4:$E$675,'📋 ORDERS'!$Q$4:$Q$675))),0)),0))*30,0))&" "&TEXT(IFERROR(INDEX('📋 ORDERS'!$N$4:$N$675,MATCH($K$4,IF($B$4="SKF Order",'📋 ORDERS'!$C$4:$C$675,IF($B$4="TATA Order",'📋 ORDERS'!$D$4:$D$675,IF($B$4="Vulcan PO",'📋 ORDERS'!$E$4:$E$675,'📋 ORDERS'!$Q$4:$Q$675))),0)),0),"0%")&" expedido","") -> ██████████████████████████████ 100% expedido
B14: 💰 LINE TOTAL (USD)
B15: =IFERROR(INDEX('📋 ORDERS'!$P$4:$P$675,MATCH($K$4,IF($B$4="SKF Order",'📋 ORDERS'!$C$4:$C$675,IF($B$4="TATA Order",'📋 ORDERS'!$D$4:$D$675,IF($B$4="Vulcan PO",'📋 ORDERS'!$E$4:$E$675,'📋 ORDERS'!$Q$4:$Q$675))),0)),"") -> 13560.8
B17: ✔ CUSTOMER DELIVERY
B18: Delivery Status | C18: SKF Collection Date | E18: Customer Delivery Date | G18: Notes
B19: =IFERROR(INDEX('📋 ORDERS'!$X$4:$X$675,MATCH($K$4,IF($B$4="SKF Order",'📋 ORDERS'!$C$4:$C$675,IF($B$4="TATA Order",'📋 ORDERS'!$D$4:$D$675,IF($B$4="Vulcan PO",'📋 ORDERS'!$E$4:$E$675,'📋 ORDERS'!$Q$4:$Q$675))),0)),"") -> 46164 | C19: =IFERROR(INDEX('📋 ORDERS'!$W$4:$W$675,MATCH($K$4,IF($B$4="SKF Order",'📋 ORDERS'!$C$4:$C$675,IF($B$4="TATA Order",'📋 ORDERS'!$D$4:$D$675,IF($B$4="Vulcan PO",'📋 ORDERS'!$E$4:$E$675,'📋 ORDERS'!$Q$4:$Q$675))),0)),"") -> F66050 | E19: =IFERROR(INDEX('📋 ORDERS'!$Y$4:$Y$675,MATCH($K$4,IF($B$4="SKF Order",'📋 ORDERS'!$C$4:$C$675,IF($B$4="TATA Order",'📋 ORDERS'!$D$4:$D$675,IF($B$4="Vulcan PO",'📋 ORDERS'!$E$4:$E$675,'📋 ORDERS'!$Q$4:$Q$675))),0)),"") -> ✔ | G19: =IFERROR(INDEX('📋 ORDERS'!$Z$4:$Z$675,MATCH($K$4,IF($B$4="SKF Order",'📋 ORDERS'!$C$4:$C$675,IF($B$4="TATA Order",'📋 ORDERS'!$D$4:$D$675,IF($B$4="Vulcan PO",'📋 ORDERS'!$E$4:$E$675,'📋 ORDERS'!$Q$4:$Q$675))),0)),"") -> 46181
B21: 📦 ORDER ITEMS
B22: # | C22: Line | D22: SKF Designation | F22: Warehouse | G22: Qty Ord. | H22: Qty Shp. | I22: Status | J22: Days
B23: =IF(IFERROR(_xludf.aggregate(15,6,(ROW('📋 ORDERS'!$B$4:$B$675)-3)/(IF($B$4="SKF Order",'📋 ORDERS'!$C$4:$C$675,IF($B$4="TATA Order",'📋 ORDERS'!$D$4:$D$675,IF($B$4="Vulcan PO",'📋 ORDERS'!$E$4:$E$675,'📋 ORDERS'!$Q$4:$Q$675)))=$K$4),1),0)=0,"",1) | C23: =IF(IFERROR(_xludf.aggregate(15,6,(ROW('📋 ORDERS'!$B$4:$B$675)-3)/(IF($B$4="SKF Order",'📋 ORDERS'!$C$4:$C$675,IF($B$4="TATA Order",'📋 ORDERS'!$D$4:$D$675,IF($B$4="Vulcan PO",'📋 ORDERS'!$E$4:$E$675,'📋 ORDERS'!$Q$4:$Q$675)))=$K$4),1),0)=0,"",IFERROR(INDEX('📋 ORDERS'!$C$4:$C$675,IFERROR(_xludf.aggregate(15,6,(ROW('📋 ORDERS'!$B$4:$B$675)-3)/(IF($B$4="SKF Order",'📋 ORDERS'!$C$4:$C$675,IF($B$4="TATA Order",'📋 ORDERS'!$D$4:$D$675,IF($B$4="Vulcan PO",'📋 ORDERS'!$E$4:$E$675,'📋 ORDERS'!$Q$4:$Q$675)))=$K$4),1),0)),"")) | D23: =IF(IFERROR(_xludf.aggregate(15,6,(ROW('📋 ORDERS'!$B$4:$B$675)-3)/(IF($B$4="SKF Order",'📋 ORDERS'!$C$4:$C$675,IF($B$4="TATA Order",'📋 ORDERS'!$D$4:$D$675,IF($B$4="Vulcan PO",'📋 ORDERS'!$E$4:$E$675,'📋 ORDERS'!$Q$4:$Q$675)))=$K$4),1),0)=0,"",IFERROR(INDEX('📋 ORDERS'!$G$4:$G$675,IFERROR(_xludf.aggregate(15,6,(ROW('📋 ORDERS'!$B$4:$B$675)-3)/(IF($B$4="SKF Order",'📋 ORDERS'!$C$4:$C$675,IF($B$4="TATA Order",'📋 ORDERS'!$D$4:$D$675,IF($B$4="Vulcan PO",'📋 ORDERS'!$E$4:$E$675,'📋 ORDERS'!$Q$4:$Q$675)))=$K$4),1),0)),"")) | F23: =IF(IFERROR(_xludf.aggregate(15,6,(ROW('📋 ORDERS'!$B$4:$B$675)-3)/(IF($B$4="SKF Order",'📋 ORDERS'!$C$4:$C$675,IF($B$4="TATA Order",'📋 ORDERS'!$D$4:$D$675,IF($B$4="Vulcan PO",'📋 ORDERS'!$E$4:$E$675,'📋 ORDERS'!$Q$4:$Q$675)))=$K$4),1),0)=0,"",IFERROR(INDEX('📋 ORDERS'!$K$4:$K$675,IFERROR(_xludf.aggregate(15,6,(ROW('📋 ORDERS'!$B$4:$B$675)-3)/(IF($B$4="SKF Order",'📋 ORDERS'!$C$4:$C$675,IF($B$4="TATA Order",'📋 ORDERS'!$D$4:$D$675,IF($B$4="Vulcan PO",'📋 ORDERS'!$E$4:$E$675,'📋 ORDERS'!$Q$4:$Q$675)))=$K$4),1),0)),"")) | G23: =IF(IFERROR(_xludf.aggregate(15,6,(ROW('📋 ORDERS'!$B$4:$B$675)-3)/(IF($B$4="SKF Order",'📋 ORDERS'!$C$4:$C$675,IF($B$4="TATA Order",'📋 ORDERS'!$D$4:$D$675,IF($B$4="Vulcan PO",'📋 ORDERS'!$E$4:$E$675,'📋 ORDERS'!$Q$4:$Q$675)))=$K$4),1),0)=0,"",IFERROR(INDEX('📋 ORDERS'!$L$4:$L$675,IFERROR(_xludf.aggregate(15,6,(ROW('📋 ORDERS'!$B$4:$B$675)-3)/(IF($B$4="SKF Order",'📋 ORDERS'!$C$4:$C$675,IF($B$4="TATA Order",'📋 ORDERS'!$D$4:$D$675,IF($B$4="Vulcan PO",'📋 ORDERS'!$E$4:$E$675,'📋 ORDERS'!$Q$4:$Q$675)))=$K$4),1),0)),"")) | H23: =IF(IFERROR(_xludf.aggregate(15,6,(ROW('📋 ORDERS'!$B$4:$B$675)-3)/(IF($B$4="SKF Order",'📋 ORDERS'!$C$4:$C$675,IF($B$4="TATA Order",'📋 ORDERS'!$D$4:$D$675,IF($B$4="Vulcan PO",'📋 ORDERS'!$E$4:$E$675,'📋 ORDERS'!$Q$4:$Q$675)))=$K$4),1),0)=0,"",IFERROR(INDEX('📋 ORDERS'!$M$4:$M$675,IFERROR(_xludf.aggregate(15,6,(ROW('📋 ORDERS'!$B$4:$B$675)-3)/(IF($B$4="SKF Order",'📋 ORDERS'!$C$4:$C$675,IF($B$4="TATA Order",'📋 ORDERS'!$D$4:$D$675,IF($B$4="Vulcan PO",'📋 ORDERS'!$E$4:$E$675,'📋 ORDERS'!$Q$4:$Q$675)))=$K$4),1),0)),"")) | I23: =IF(IFERROR(_xludf.aggregate(15,6,(ROW('📋 ORDERS'!$B$4:$B$675)-3)/(IF($B$4="SKF Order",'📋 ORDERS'!$C$4:$C$675,IF($B$4="TATA Order",'📋 ORDERS'!$D$4:$D$675,IF($B$4="Vulcan PO",'📋 ORDERS'!$E$4:$E$675,'📋 ORDERS'!$Q$4:$Q$675)))=$K$4),1),0)=0,"",IFERROR(INDEX('📋 ORDERS'!$R$4:$R$675,IFERROR(_xludf.aggregate(15,6,(ROW('📋 ORDERS'!$B$4:$B$675)-3)/(IF($B$4="SKF Order",'📋 ORDERS'!$C$4:$C$675,IF($B$4="TATA Order",'📋 ORDERS'!$D$4:$D$675,IF($B$4="Vulcan PO",'📋 ORDERS'!$E$4:$E$675,'📋 ORDERS'!$Q$4:$Q$675)))=$K$4),1),0)),"")) | J23: =IF(IFERROR(_xludf.aggregate(15,6,(ROW('📋 ORDERS'!$B$4:$B$675)-3)/(IF($B$4="SKF Order",'📋 ORDERS'!$C$4:$C$675,IF($B$4="TATA Order",'📋 ORDERS'!$D$4:$D$675,IF($B$4="Vulcan PO",'📋 ORDERS'!$E$4:$E$675,'📋 ORDERS'!$Q$4:$Q$675)))=$K$4),1),0)=0,"",IFERROR(INDEX('📋 ORDERS'!$S$4:$S$675,IFERROR(_xludf.aggregate(15,6,(ROW('📋 ORDERS'!$B$4:$B$675)-3)/(IF($B$4="SKF Order",'📋 ORDERS'!$C$4:$C$675,IF($B$4="TATA Order",'📋 ORDERS'!$D$4:$D$675,IF($B$4="Vulcan PO",'📋 ORDERS'!$E$4:$E$675,'📋 ORDERS'!$Q$4:$Q$675)))=$K$4),1),0)),""))
B24: =IF(IFERROR(_xludf.aggregate(15,6,(ROW('📋 ORDERS'!$B$4:$B$675)-3)/(IF($B$4="SKF Order",'📋 ORDERS'!$C$4:$C$675,IF($B$4="TATA Order",'📋 ORDERS'!$D$4:$D$675,IF($B$4="Vulcan PO",'📋 ORDERS'!$E$4:$E$675,'📋 ORDERS'!$Q$4:$Q$675)))=$K$4),2),0)=0,"",2) | C24: =IF(IFERROR(_xludf.aggregate(15,6,(ROW('📋 ORDERS'!$B$4:$B$675)-3)/(IF($B$4="SKF Order",'📋 ORDERS'!$C$4:$C$675,IF($B$4="TATA Order",'📋 ORDERS'!$D$4:$D$675,IF($B$4="Vulcan PO",'📋 ORDERS'!$E$4:$E$675,'📋 ORDERS'!$Q$4:$Q$675)))=$K$4),2),0)=0,"",IFERROR(INDEX('📋 ORDERS'!$C$4:$C$675,IFERROR(_xludf.aggregate(15,6,(ROW('📋 ORDERS'!$B$4:$B$675)-3)/(IF($B$4="SKF Order",'📋 ORDERS'!$C$4:$C$675,IF($B$4="TATA Order",'📋 ORDERS'!$D$4:$D$675,IF($B$4="Vulcan PO",'📋 ORDERS'!$E$4:$E$675,'📋 ORDERS'!$Q$4:$Q$675)))=$K$4),2),0)),"")) | D24: =IF(IFERROR(_xludf.aggregate(15,6,(ROW('📋 ORDERS'!$B$4:$B$675)-3)/(IF($B$4="SKF Order",'📋 ORDERS'!$C$4:$C$675,IF($B$4="TATA Order",'📋 ORDERS'!$D$4:$D$675,IF($B$4="Vulcan PO",'📋 ORDERS'!$E$4:$E$675,'📋 ORDERS'!$Q$4:$Q$675)))=$K$4),2),0)=0,"",IFERROR(INDEX('📋 ORDERS'!$G$4:$G$675,IFERROR(_xludf.aggregate(15,6,(ROW('📋 ORDERS'!$B$4:$B$675)-3)/(IF($B$4="SKF Order",'📋 ORDERS'!$C$4:$C$675,IF($B$4="TATA Order",'📋 ORDERS'!$D$4:$D$675,IF($B$4="Vulcan PO",'📋 ORDERS'!$E$4:$E$675,'📋 ORDERS'!$Q$4:$Q$675)))=$K$4),2),0)),"")) | F24: =IF(IFERROR(_xludf.aggregate(15,6,(ROW('📋 ORDERS'!$B$4:$B$675)-3)/(IF($B$4="SKF Order",'📋 ORDERS'!$C$4:$C$675,IF($B$4="TATA Order",'📋 ORDERS'!$D$4:$D$675,IF($B$4="Vulcan PO",'📋 ORDERS'!$E$4:$E$675,'📋 ORDERS'!$Q$4:$Q$675)))=$K$4),2),0)=0,"",IFERROR(INDEX('📋 ORDERS'!$K$4:$K$675,IFERROR(_xludf.aggregate(15,6,(ROW('📋 ORDERS'!$B$4:$B$675)-3)/(IF($B$4="SKF Order",'📋 ORDERS'!$C$4:$C$675,IF($B$4="TATA Order",'📋 ORDERS'!$D$4:$D$675,IF($B$4="Vulcan PO",'📋 ORDERS'!$E$4:$E$675,'📋 ORDERS'!$Q$4:$Q$675)))=$K$4),2),0)),"")) | G24: =IF(IFERROR(_xludf.aggregate(15,6,(ROW('📋 ORDERS'!$B$4:$B$675)-3)/(IF($B$4="SKF Order",'📋 ORDERS'!$C$4:$C$675,IF($B$4="TATA Order",'📋 ORDERS'!$D$4:$D$675,IF($B$4="Vulcan PO",'📋 ORDERS'!$E$4:$E$675,'📋 ORDERS'!$Q$4:$Q$675)))=$K$4),2),0)=0,"",IFERROR(INDEX('📋 ORDERS'!$L$4:$L$675,IFERROR(_xludf.aggregate(15,6,(ROW('📋 ORDERS'!$B$4:$B$675)-3)/(IF($B$4="SKF Order",'📋 ORDERS'!$C$4:$C$675,IF($B$4="TATA Order",'📋 ORDERS'!$D$4:$D$675,IF($B$4="Vulcan PO",'📋 ORDERS'!$E$4:$E$675,'📋 ORDERS'!$Q$4:$Q$675)))=$K$4),2),0)),"")) | H24: =IF(IFERROR(_xludf.aggregate(15,6,(ROW('📋 ORDERS'!$B$4:$B$675)-3)/(IF($B$4="SKF Order",'📋 ORDERS'!$C$4:$C$675,IF($B$4="TATA Order",'📋 ORDERS'!$D$4:$D$675,IF($B$4="Vulcan PO",'📋 ORDERS'!$E$4:$E$675,'📋 ORDERS'!$Q$4:$Q$675)))=$K$4),2),0)=0,"",IFERROR(INDEX('📋 ORDERS'!$M$4:$M$675,IFERROR(_xludf.aggregate(15,6,(ROW('📋 ORDERS'!$B$4:$B$675)-3)/(IF($B$4="SKF Order",'📋 ORDERS'!$C$4:$C$675,IF($B$4="TATA Order",'📋 ORDERS'!$D$4:$D$675,IF($B$4="Vulcan PO",'📋 ORDERS'!$E$4:$E$675,'📋 ORDERS'!$Q$4:$Q$675)))=$K$4),2),0)),"")) | I24: =IF(IFERROR(_xludf.aggregate(15,6,(ROW('📋 ORDERS'!$B$4:$B$675)-3)/(IF($B$4="SKF Order",'📋 ORDERS'!$C$4:$C$675,IF($B$4="TATA Order",'📋 ORDERS'!$D$4:$D$675,IF($B$4="Vulcan PO",'📋 ORDERS'!$E$4:$E$675,'📋 ORDERS'!$Q$4:$Q$675)))=$K$4),2),0)=0,"",IFERROR(INDEX('📋 ORDERS'!$R$4:$R$675,IFERROR(_xludf.aggregate(15,6,(ROW('📋 ORDERS'!$B$4:$B$675)-3)/(IF($B$4="SKF Order",'📋 ORDERS'!$C$4:$C$675,IF($B$4="TATA Order",'📋 ORDERS'!$D$4:$D$675,IF($B$4="Vulcan PO",'📋 ORDERS'!$E$4:$E$675,'📋 ORDERS'!$Q$4:$Q$675)))=$K$4),2),0)),"")) | J24: =IF(IFERROR(_xludf.aggregate(15,6,(ROW('📋 ORDERS'!$B$4:$B$675)-3)/(IF($B$4="SKF Order",'📋 ORDERS'!$C$4:$C$675,IF($B$4="TATA Order",'📋 ORDERS'!$D$4:$D$675,IF($B$4="Vulcan PO",'📋 ORDERS'!$E$4:$E$675,'📋 ORDERS'!$Q$4:$Q$675)))=$K$4),2),0)=0,"",IFERROR(INDEX('📋 ORDERS'!$S$4:$S$675,IFERROR(_xludf.aggregate(15,6,(ROW('📋 ORDERS'!$B$4:$B$675)-3)/(IF($B$4="SKF Order",'📋 ORDERS'!$C$4:$C$675,IF($B$4="TATA Order",'📋 ORDERS'!$D$4:$D$675,IF($B$4="Vulcan PO",'📋 ORDERS'!$E$4:$E$675,'📋 ORDERS'!$Q$4:$Q$675)))=$K$4),2),0)),""))
B25: =IF(IFERROR(_xludf.aggregate(15,6,(ROW('📋 ORDERS'!$B$4:$B$675)-3)/(IF($B$4="SKF Order",'📋 ORDERS'!$C$4:$C$675,IF($B$4="TATA Order",'📋 ORDERS'!$D$4:$D$675,IF($B$4="Vulcan PO",'📋 ORDERS'!$E$4:$E$675,'📋 ORDERS'!$Q$4:$Q$675)))=$K$4),3),0)=0,"",3) | C25: =IF(IFERROR(_xludf.aggregate(15,6,(ROW('📋 ORDERS'!$B$4:$B$675)-3)/(IF($B$4="SKF Order",'📋 ORDERS'!$C$4:$C$675,IF($B$4="TATA Order",'📋 ORDERS'!$D$4:$D$675,IF($B$4="Vulcan PO",'📋 ORDERS'!$E$4:$E$675,'📋 ORDERS'!$Q$4:$Q$675)))=$K$4),3),0)=0,"",IFERROR(INDEX('📋 ORDERS'!$C$4:$C$675,IFERROR(_xludf.aggregate(15,6,(ROW('📋 ORDERS'!$B$4:$B$675)-3)/(IF($B$4="SKF Order",'📋 ORDERS'!$C$4:$C$675,IF($B$4="TATA Order",'📋 ORDERS'!$D$4:$D$675,IF($B$4="Vulcan PO",'📋 ORDERS'!$E$4:$E$675,'📋 ORDERS'!$Q$4:$Q$675)))=$K$4),3),0)),"")) | D25: =IF(IFERROR(_xludf.aggregate(15,6,(ROW('📋 ORDERS'!$B$4:$B$675)-3)/(IF($B$4="SKF Order",'📋 ORDERS'!$C$4:$C$675,IF($B$4="TATA Order",'📋 ORDERS'!$D$4:$D$675,IF($B$4="Vulcan PO",'📋 ORDERS'!$E$4:$E$675,'📋 ORDERS'!$Q$4:$Q$675)))=$K$4),3),0)=0,"",IFERROR(INDEX('📋 ORDERS'!$G$4:$G$675,IFERROR(_xludf.aggregate(15,6,(ROW('📋 ORDERS'!$B$4:$B$675)-3)/(IF($B$4="SKF Order",'📋 ORDERS'!$C$4:$C$675,IF($B$4="TATA Order",'📋 ORDERS'!$D$4:$D$675,IF($B$4="Vulcan PO",'📋 ORDERS'!$E$4:$E$675,'📋 ORDERS'!$Q$4:$Q$675)))=$K$4),3),0)),"")) | F25: =IF(IFERROR(_xludf.aggregate(15,6,(ROW('📋 ORDERS'!$B$4:$B$675)-3)/(IF($B$4="SKF Order",'📋 ORDERS'!$C$4:$C$675,IF($B$4="TATA Order",'📋 ORDERS'!$D$4:$D$675,IF($B$4="Vulcan PO",'📋 ORDERS'!$E$4:$E$675,'📋 ORDERS'!$Q$4:$Q$675)))=$K$4),3),0)=0,"",IFERROR(INDEX('📋 ORDERS'!$K$4:$K$675,IFERROR(_xludf.aggregate(15,6,(ROW('📋 ORDERS'!$B$4:$B$675)-3)/(IF($B$4="SKF Order",'📋 ORDERS'!$C$4:$C$675,IF($B$4="TATA Order",'📋 ORDERS'!$D$4:$D$675,IF($B$4="Vulcan PO",'📋 ORDERS'!$E$4:$E$675,'📋 ORDERS'!$Q$4:$Q$675)))=$K$4),3),0)),"")) | G25: =IF(IFERROR(_xludf.aggregate(15,6,(ROW('📋 ORDERS'!$B$4:$B$675)-3)/(IF($B$4="SKF Order",'📋 ORDERS'!$C$4:$C$675,IF($B$4="TATA Order",'📋 ORDERS'!$D$4:$D$675,IF($B$4="Vulcan PO",'📋 ORDERS'!$E$4:$E$675,'📋 ORDERS'!$Q$4:$Q$675)))=$K$4),3),0)=0,"",IFERROR(INDEX('📋 ORDERS'!$L$4:$L$675,IFERROR(_xludf.aggregate(15,6,(ROW('📋 ORDERS'!$B$4:$B$675)-3)/(IF($B$4="SKF Order",'📋 ORDERS'!$C$4:$C$675,IF($B$4="TATA Order",'📋 ORDERS'!$D$4:$D$675,IF($B$4="Vulcan PO",'📋 ORDERS'!$E$4:$E$675,'📋 ORDERS'!$Q$4:$Q$675)))=$K$4),3),0)),"")) | H25: =IF(IFERROR(_xludf.aggregate(15,6,(ROW('📋 ORDERS'!$B$4:$B$675)-3)/(IF($B$4="SKF Order",'📋 ORDERS'!$C$4:$C$675,IF($B$4="TATA Order",'📋 ORDERS'!$D$4:$D$675,IF($B$4="Vulcan PO",'📋 ORDERS'!$E$4:$E$675,'📋 ORDERS'!$Q$4:$Q$675)))=$K$4),3),0)=0,"",IFERROR(INDEX('📋 ORDERS'!$M$4:$M$675,IFERROR(_xludf.aggregate(15,6,(ROW('📋 ORDERS'!$B$4:$B$675)-3)/(IF($B$4="SKF Order",'📋 ORDERS'!$C$4:$C$675,IF($B$4="TATA Order",'📋 ORDERS'!$D$4:$D$675,IF($B$4="Vulcan PO",'📋 ORDERS'!$E$4:$E$675,'📋 ORDERS'!$Q$4:$Q$675)))=$K$4),3),0)),"")) | I25: =IF(IFERROR(_xludf.aggregate(15,6,(ROW('📋 ORDERS'!$B$4:$B$675)-3)/(IF($B$4="SKF Order",'📋 ORDERS'!$C$4:$C$675,IF($B$4="TATA Order",'📋 ORDERS'!$D$4:$D$675,IF($B$4="Vulcan PO",'📋 ORDERS'!$E$4:$E$675,'📋 ORDERS'!$Q$4:$Q$675)))=$K$4),3),0)=0,"",IFERROR(INDEX('📋 ORDERS'!$R$4:$R$675,IFERROR(_xludf.aggregate(15,6,(ROW('📋 ORDERS'!$B$4:$B$675)-3)/(IF($B$4="SKF Order",'📋 ORDERS'!$C$4:$C$675,IF($B$4="TATA Order",'📋 ORDERS'!$D$4:$D$675,IF($B$4="Vulcan PO",'📋 ORDERS'!$E$4:$E$675,'📋 ORDERS'!$Q$4:$Q$675)))=$K$4),3),0)),"")) | J25: =IF(IFERROR(_xludf.aggregate(15,6,(ROW('📋 ORDERS'!$B$4:$B$675)-3)/(IF($B$4="SKF Order",'📋 ORDERS'!$C$4:$C$675,IF($B$4="TATA Order",'📋 ORDERS'!$D$4:$D$675,IF($B$4="Vulcan PO",'📋 ORDERS'!$E$4:$E$675,'📋 ORDERS'!$Q$4:$Q$675)))=$K$4),3),0)=0,"",IFERROR(INDEX('📋 ORDERS'!$S$4:$S$675,IFERROR(_xludf.aggregate(15,6,(ROW('📋 ORDERS'!$B$4:$B$675)-3)/(IF($B$4="SKF Order",'📋 ORDERS'!$C$4:$C$675,IF($B$4="TATA Order",'📋 ORDERS'!$D$4:$D$675,IF($B$4="Vulcan PO",'📋 ORDERS'!$E$4:$E$675,'📋 ORDERS'!$Q$4:$Q$675)))=$K$4),3),0)),""))
B26: =IF(IFERROR(_xludf.aggregate(15,6,(ROW('📋 ORDERS'!$B$4:$B$675)-3)/(IF($B$4="SKF Order",'📋 ORDERS'!$C$4:$C$675,IF($B$4="TATA Order",'📋 ORDERS'!$D$4:$D$675,IF($B$4="Vulcan PO",'📋 ORDERS'!$E$4:$E$675,'📋 ORDERS'!$Q$4:$Q$675)))=$K$4),4),0)=0,"",4) | C26: =IF(IFERROR(_xludf.aggregate(15,6,(ROW('📋 ORDERS'!$B$4:$B$675)-3)/(IF($B$4="SKF Order",'📋 ORDERS'!$C$4:$C$675,IF($B$4="TATA Order",'📋 ORDERS'!$D$4:$D$675,IF($B$4="Vulcan PO",'📋 ORDERS'!$E$4:$E$675,'📋 ORDERS'!$Q$4:$Q$675)))=$K$4),4),0)=0,"",IFERROR(INDEX('📋 ORDERS'!$C$4:$C$675,IFERROR(_xludf.aggregate(15,6,(ROW('📋 ORDERS'!$B$4:$B$675)-3)/(IF($B$4="SKF Order",'📋 ORDERS'!$C$4:$C$675,IF($B$4="TATA Order",'📋 ORDERS'!$D$4:$D$675,IF($B$4="Vulcan PO",'📋 ORDERS'!$E$4:$E$675,'📋 ORDERS'!$Q$4:$Q$675)))=$K$4),4),0)),"")) | D26: =IF(IFERROR(_xludf.aggregate(15,6,(ROW('📋 ORDERS'!$B$4:$B$675)-3)/(IF($B$4="SKF Order",'📋 ORDERS'!$C$4:$C$675,IF($B$4="TATA Order",'📋 ORDERS'!$D$4:$D$675,IF($B$4="Vulcan PO",'📋 ORDERS'!$E$4:$E$675,'📋 ORDERS'!$Q$4:$Q$675)))=$K$4),4),0)=0,"",IFERROR(INDEX('📋 ORDERS'!$G$4:$G$675,IFERROR(_xludf.aggregate(15,6,(ROW('📋 ORDERS'!$B$4:$B$675)-3)/(IF($B$4="SKF Order",'📋 ORDERS'!$C$4:$C$675,IF($B$4="TATA Order",'📋 ORDERS'!$D$4:$D$675,IF($B$4="Vulcan PO",'📋 ORDERS'!$E$4:$E$675,'📋 ORDERS'!$Q$4:$Q$675)))=$K$4),4),0)),"")) | F26: =IF(IFERROR(_xludf.aggregate(15,6,(ROW('📋 ORDERS'!$B$4:$B$675)-3)/(IF($B$4="SKF Order",'📋 ORDERS'!$C$4:$C$675,IF($B$4="TATA Order",'📋 ORDERS'!$D$4:$D$675,IF($B$4="Vulcan PO",'📋 ORDERS'!$E$4:$E$675,'📋 ORDERS'!$Q$4:$Q$675)))=$K$4),4),0)=0,"",IFERROR(INDEX('📋 ORDERS'!$K$4:$K$675,IFERROR(_xludf.aggregate(15,6,(ROW('📋 ORDERS'!$B$4:$B$675)-3)/(IF($B$4="SKF Order",'📋 ORDERS'!$C$4:$C$675,IF($B$4="TATA Order",'📋 ORDERS'!$D$4:$D$675,IF($B$4="Vulcan PO",'📋 ORDERS'!$E$4:$E$675,'📋 ORDERS'!$Q$4:$Q$675)))=$K$4),4),0)),"")) | G26: =IF(IFERROR(_xludf.aggregate(15,6,(ROW('📋 ORDERS'!$B$4:$B$675)-3)/(IF($B$4="SKF Order",'📋 ORDERS'!$C$4:$C$675,IF($B$4="TATA Order",'📋 ORDERS'!$D$4:$D$675,IF($B$4="Vulcan PO",'📋 ORDERS'!$E$4:$E$675,'📋 ORDERS'!$Q$4:$Q$675)))=$K$4),4),0)=0,"",IFERROR(INDEX('📋 ORDERS'!$L$4:$L$675,IFERROR(_xludf.aggregate(15,6,(ROW('📋 ORDERS'!$B$4:$B$675)-3)/(IF($B$4="SKF Order",'📋 ORDERS'!$C$4:$C$675,IF($B$4="TATA Order",'📋 ORDERS'!$D$4:$D$675,IF($B$4="Vulcan PO",'📋 ORDERS'!$E$4:$E$675,'📋 ORDERS'!$Q$4:$Q$675)))=$K$4),4),0)),"")) | H26: =IF(IFERROR(_xludf.aggregate(15,6,(ROW('📋 ORDERS'!$B$4:$B$675)-3)/(IF($B$4="SKF Order",'📋 ORDERS'!$C$4:$C$675,IF($B$4="TATA Order",'📋 ORDERS'!$D$4:$D$675,IF($B$4="Vulcan PO",'📋 ORDERS'!$E$4:$E$675,'📋 ORDERS'!$Q$4:$Q$675)))=$K$4),4),0)=0,"",IFERROR(INDEX('📋 ORDERS'!$M$4:$M$675,IFERROR(_xludf.aggregate(15,6,(ROW('📋 ORDERS'!$B$4:$B$675)-3)/(IF($B$4="SKF Order",'📋 ORDERS'!$C$4:$C$675,IF($B$4="TATA Order",'📋 ORDERS'!$D$4:$D$675,IF($B$4="Vulcan PO",'📋 ORDERS'!$E$4:$E$675,'📋 ORDERS'!$Q$4:$Q$675)))=$K$4),4),0)),"")) | I26: =IF(IFERROR(_xludf.aggregate(15,6,(ROW('📋 ORDERS'!$B$4:$B$675)-3)/(IF($B$4="SKF Order",'📋 ORDERS'!$C$4:$C$675,IF($B$4="TATA Order",'📋 ORDERS'!$D$4:$D$675,IF($B$4="Vulcan PO",'📋 ORDERS'!$E$4:$E$675,'📋 ORDERS'!$Q$4:$Q$675)))=$K$4),4),0)=0,"",IFERROR(INDEX('📋 ORDERS'!$R$4:$R$675,IFERROR(_xludf.aggregate(15,6,(ROW('📋 ORDERS'!$B$4:$B$675)-3)/(IF($B$4="SKF Order",'📋 ORDERS'!$C$4:$C$675,IF($B$4="TATA Order",'📋 ORDERS'!$D$4:$D$675,IF($B$4="Vulcan PO",'📋 ORDERS'!$E$4:$E$675,'📋 ORDERS'!$Q$4:$Q$675)))=$K$4),4),0)),"")) | J26: =IF(IFERROR(_xludf.aggregate(15,6,(ROW('📋 ORDERS'!$B$4:$B$675)-3)/(IF($B$4="SKF Order",'📋 ORDERS'!$C$4:$C$675,IF($B$4="TATA Order",'📋 ORDERS'!$D$4:$D$675,IF($B$4="Vulcan PO",'📋 ORDERS'!$E$4:$E$675,'📋 ORDERS'!$Q$4:$Q$675)))=$K$4),4),0)=0,"",IFERROR(INDEX('📋 ORDERS'!$S$4:$S$675,IFERROR(_xludf.aggregate(15,6,(ROW('📋 ORDERS'!$B$4:$B$675)-3)/(IF($B$4="SKF Order",'📋 ORDERS'!$C$4:$C$675,IF($B$4="TATA Order",'📋 ORDERS'!$D$4:$D$675,IF($B$4="Vulcan PO",'📋 ORDERS'!$E$4:$E$675,'📋 ORDERS'!$Q$4:$Q$675)))=$K$4),4),0)),""))
B27: =IF(IFERROR(_xludf.aggregate(15,6,(ROW('📋 ORDERS'!$B$4:$B$675)-3)/(IF($B$4="SKF Order",'📋 ORDERS'!$C$4:$C$675,IF($B$4="TATA Order",'📋 ORDERS'!$D$4:$D$675,IF($B$4="Vulcan PO",'📋 ORDERS'!$E$4:$E$675,'📋 ORDERS'!$Q$4:$Q$675)))=$K$4),5),0)=0,"",5) | C27: =IF(IFERROR(_xludf.aggregate(15,6,(ROW('📋 ORDERS'!$B$4:$B$675)-3)/(IF($B$4="SKF Order",'📋 ORDERS'!$C$4:$C$675,IF($B$4="TATA Order",'📋 ORDERS'!$D$4:$D$675,IF($B$4="Vulcan PO",'📋 ORDERS'!$E$4:$E$675,'📋 ORDERS'!$Q$4:$Q$675)))=$K$4),5),0)=0,"",IFERROR(INDEX('📋 ORDERS'!$C$4:$C$675,IFERROR(_xludf.aggregate(15,6,(ROW('📋 ORDERS'!$B$4:$B$675)-3)/(IF($B$4="SKF Order",'📋 ORDERS'!$C$4:$C$675,IF($B$4="TATA Order",'📋 ORDERS'!$D$4:$D$675,IF($B$4="Vulcan PO",'📋 ORDERS'!$E$4:$E$675,'📋 ORDERS'!$Q$4:$Q$675)))=$K$4),5),0)),"")) | D27: =IF(IFERROR(_xludf.aggregate(15,6,(ROW('📋 ORDERS'!$B$4:$B$675)-3)/(IF($B$4="SKF Order",'📋 ORDERS'!$C$4:$C$675,IF($B$4="TATA Order",'📋 ORDERS'!$D$4:$D$675,IF($B$4="Vulcan PO",'📋 ORDERS'!$E$4:$E$675,'📋 ORDERS'!$Q$4:$Q$675)))=$K$4),5),0)=0,"",IFERROR(INDEX('📋 ORDERS'!$G$4:$G$675,IFERROR(_xludf.aggregate(15,6,(ROW('📋 ORDERS'!$B$4:$B$675)-3)/(IF($B$4="SKF Order",'📋 ORDERS'!$C$4:$C$675,IF($B$4="TATA Order",'📋 ORDERS'!$D$4:$D$675,IF($B$4="Vulcan PO",'📋 ORDERS'!$E$4:$E$675,'📋 ORDERS'!$Q$4:$Q$675)))=$K$4),5),0)),"")) | F27: =IF(IFERROR(_xludf.aggregate(15,6,(ROW('📋 ORDERS'!$B$4:$B$675)-3)/(IF($B$4="SKF Order",'📋 ORDERS'!$C$4:$C$675,IF($B$4="TATA Order",'📋 ORDERS'!$D$4:$D$675,IF($B$4="Vulcan PO",'📋 ORDERS'!$E$4:$E$675,'📋 ORDERS'!$Q$4:$Q$675)))=$K$4),5),0)=0,"",IFERROR(INDEX('📋 ORDERS'!$K$4:$K$675,IFERROR(_xludf.aggregate(15,6,(ROW('📋 ORDERS'!$B$4:$B$675)-3)/(IF($B$4="SKF Order",'📋 ORDERS'!$C$4:$C$675,IF($B$4="TATA Order",'📋 ORDERS'!$D$4:$D$675,IF($B$4="Vulcan PO",'📋 ORDERS'!$E$4:$E$675,'📋 ORDERS'!$Q$4:$Q$675)))=$K$4),5),0)),"")) | G27: =IF(IFERROR(_xludf.aggregate(15,6,(ROW('📋 ORDERS'!$B$4:$B$675)-3)/(IF($B$4="SKF Order",'📋 ORDERS'!$C$4:$C$675,IF($B$4="TATA Order",'📋 ORDERS'!$D$4:$D$675,IF($B$4="Vulcan PO",'📋 ORDERS'!$E$4:$E$675,'📋 ORDERS'!$Q$4:$Q$675)))=$K$4),5),0)=0,"",IFERROR(INDEX('📋 ORDERS'!$L$4:$L$675,IFERROR(_xludf.aggregate(15,6,(ROW('📋 ORDERS'!$B$4:$B$675)-3)/(IF($B$4="SKF Order",'📋 ORDERS'!$C$4:$C$675,IF($B$4="TATA Order",'📋 ORDERS'!$D$4:$D$675,IF($B$4="Vulcan PO",'📋 ORDERS'!$E$4:$E$675,'📋 ORDERS'!$Q$4:$Q$675)))=$K$4),5),0)),"")) | H27: =IF(IFERROR(_xludf.aggregate(15,6,(ROW('📋 ORDERS'!$B$4:$B$675)-3)/(IF($B$4="SKF Order",'📋 ORDERS'!$C$4:$C$675,IF($B$4="TATA Order",'📋 ORDERS'!$D$4:$D$675,IF($B$4="Vulcan PO",'📋 ORDERS'!$E$4:$E$675,'📋 ORDERS'!$Q$4:$Q$675)))=$K$4),5),0)=0,"",IFERROR(INDEX('📋 ORDERS'!$M$4:$M$675,IFERROR(_xludf.aggregate(15,6,(ROW('📋 ORDERS'!$B$4:$B$675)-3)/(IF($B$4="SKF Order",'📋 ORDERS'!$C$4:$C$675,IF($B$4="TATA Order",'📋 ORDERS'!$D$4:$D$675,IF($B$4="Vulcan PO",'📋 ORDERS'!$E$4:$E$675,'📋 ORDERS'!$Q$4:$Q$675)))=$K$4),5),0)),"")) | I27: =IF(IFERROR(_xludf.aggregate(15,6,(ROW('📋 ORDERS'!$B$4:$B$675)-3)/(IF($B$4="SKF Order",'📋 ORDERS'!$C$4:$C$675,IF($B$4="TATA Order",'📋 ORDERS'!$D$4:$D$675,IF($B$4="Vulcan PO",'📋 ORDERS'!$E$4:$E$675,'📋 ORDERS'!$Q$4:$Q$675)))=$K$4),5),0)=0,"",IFERROR(INDEX('📋 ORDERS'!$R$4:$R$675,IFERROR(_xludf.aggregate(15,6,(ROW('📋 ORDERS'!$B$4:$B$675)-3)/(IF($B$4="SKF Order",'📋 ORDERS'!$C$4:$C$675,IF($B$4="TATA Order",'📋 ORDERS'!$D$4:$D$675,IF($B$4="Vulcan PO",'📋 ORDERS'!$E$4:$E$675,'📋 ORDERS'!$Q$4:$Q$675)))=$K$4),5),0)),"")) | J27: =IF(IFERROR(_xludf.aggregate(15,6,(ROW('📋 ORDERS'!$B$4:$B$675)-3)/(IF($B$4="SKF Order",'📋 ORDERS'!$C$4:$C$675,IF($B$4="TATA Order",'📋 ORDERS'!$D$4:$D$675,IF($B$4="Vulcan PO",'📋 ORDERS'!$E$4:$E$675,'📋 ORDERS'!$Q$4:$Q$675)))=$K$4),5),0)=0,"",IFERROR(INDEX('📋 ORDERS'!$S$4:$S$675,IFERROR(_xludf.aggregate(15,6,(ROW('📋 ORDERS'!$B$4:$B$675)-3)/(IF($B$4="SKF Order",'📋 ORDERS'!$C$4:$C$675,IF($B$4="TATA Order",'📋 ORDERS'!$D$4:$D$675,IF($B$4="Vulcan PO",'📋 ORDERS'!$E$4:$E$675,'📋 ORDERS'!$Q$4:$Q$675)))=$K$4),5),0)),""))
B28: =IF(IFERROR(_xludf.aggregate(15,6,(ROW('📋 ORDERS'!$B$4:$B$675)-3)/(IF($B$4="SKF Order",'📋 ORDERS'!$C$4:$C$675,IF($B$4="TATA Order",'📋 ORDERS'!$D$4:$D$675,IF($B$4="Vulcan PO",'📋 ORDERS'!$E$4:$E$675,'📋 ORDERS'!$Q$4:$Q$675)))=$K$4),6),0)=0,"",6) | C28: =IF(IFERROR(_xludf.aggregate(15,6,(ROW('📋 ORDERS'!$B$4:$B$675)-3)/(IF($B$4="SKF Order",'📋 ORDERS'!$C$4:$C$675,IF($B$4="TATA Order",'📋 ORDERS'!$D$4:$D$675,IF($B$4="Vulcan PO",'📋 ORDERS'!$E$4:$E$675,'📋 ORDERS'!$Q$4:$Q$675)))=$K$4),6),0)=0,"",IFERROR(INDEX('📋 ORDERS'!$C$4:$C$675,IFERROR(_xludf.aggregate(15,6,(ROW('📋 ORDERS'!$B$4:$B$675)-3)/(IF($B$4="SKF Order",'📋 ORDERS'!$C$4:$C$675,IF($B$4="TATA Order",'📋 ORDERS'!$D$4:$D$675,IF($B$4="Vulcan PO",'📋 ORDERS'!$E$4:$E$675,'📋 ORDERS'!$Q$4:$Q$675)))=$K$4),6),0)),"")) | D28: =IF(IFERROR(_xludf.aggregate(15,6,(ROW('📋 ORDERS'!$B$4:$B$675)-3)/(IF($B$4="SKF Order",'📋 ORDERS'!$C$4:$C$675,IF($B$4="TATA Order",'📋 ORDERS'!$D$4:$D$675,IF($B$4="Vulcan PO",'📋 ORDERS'!$E$4:$E$675,'📋 ORDERS'!$Q$4:$Q$675)))=$K$4),6),0)=0,"",IFERROR(INDEX('📋 ORDERS'!$G$4:$G$675,IFERROR(_xludf.aggregate(15,6,(ROW('📋 ORDERS'!$B$4:$B$675)-3)/(IF($B$4="SKF Order",'📋 ORDERS'!$C$4:$C$675,IF($B$4="TATA Order",'📋 ORDERS'!$D$4:$D$675,IF($B$4="Vulcan PO",'📋 ORDERS'!$E$4:$E$675,'📋 ORDERS'!$Q$4:$Q$675)))=$K$4),6),0)),"")) | F28: =IF(IFERROR(_xludf.aggregate(15,6,(ROW('📋 ORDERS'!$B$4:$B$675)-3)/(IF($B$4="SKF Order",'📋 ORDERS'!$C$4:$C$675,IF($B$4="TATA Order",'📋 ORDERS'!$D$4:$D$675,IF($B$4="Vulcan PO",'📋 ORDERS'!$E$4:$E$675,'📋 ORDERS'!$Q$4:$Q$675)))=$K$4),6),0)=0,"",IFERROR(INDEX('📋 ORDERS'!$K$4:$K$675,IFERROR(_xludf.aggregate(15,6,(ROW('📋 ORDERS'!$B$4:$B$675)-3)/(IF($B$4="SKF Order",'📋 ORDERS'!$C$4:$C$675,IF($B$4="TATA Order",'📋 ORDERS'!$D$4:$D$675,IF($B$4="Vulcan PO",'📋 ORDERS'!$E$4:$E$675,'📋 ORDERS'!$Q$4:$Q$675)))=$K$4),6),0)),"")) | G28: =IF(IFERROR(_xludf.aggregate(15,6,(ROW('📋 ORDERS'!$B$4:$B$675)-3)/(IF($B$4="SKF Order",'📋 ORDERS'!$C$4:$C$675,IF($B$4="TATA Order",'📋 ORDERS'!$D$4:$D$675,IF($B$4="Vulcan PO",'📋 ORDERS'!$E$4:$E$675,'📋 ORDERS'!$Q$4:$Q$675)))=$K$4),6),0)=0,"",IFERROR(INDEX('📋 ORDERS'!$L$4:$L$675,IFERROR(_xludf.aggregate(15,6,(ROW('📋 ORDERS'!$B$4:$B$675)-3)/(IF($B$4="SKF Order",'📋 ORDERS'!$C$4:$C$675,IF($B$4="TATA Order",'📋 ORDERS'!$D$4:$D$675,IF($B$4="Vulcan PO",'📋 ORDERS'!$E$4:$E$675,'📋 ORDERS'!$Q$4:$Q$675)))=$K$4),6),0)),"")) | H28: =IF(IFERROR(_xludf.aggregate(15,6,(ROW('📋 ORDERS'!$B$4:$B$675)-3)/(IF($B$4="SKF Order",'📋 ORDERS'!$C$4:$C$675,IF($B$4="TATA Order",'📋 ORDERS'!$D$4:$D$675,IF($B$4="Vulcan PO",'📋 ORDERS'!$E$4:$E$675,'📋 ORDERS'!$Q$4:$Q$675)))=$K$4),6),0)=0,"",IFERROR(INDEX('📋 ORDERS'!$M$4:$M$675,IFERROR(_xludf.aggregate(15,6,(ROW('📋 ORDERS'!$B$4:$B$675)-3)/(IF($B$4="SKF Order",'📋 ORDERS'!$C$4:$C$675,IF($B$4="TATA Order",'📋 ORDERS'!$D$4:$D$675,IF($B$4="Vulcan PO",'📋 ORDERS'!$E$4:$E$675,'📋 ORDERS'!$Q$4:$Q$675)))=$K$4),6),0)),"")) | I28: =IF(IFERROR(_xludf.aggregate(15,6,(ROW('📋 ORDERS'!$B$4:$B$675)-3)/(IF($B$4="SKF Order",'📋 ORDERS'!$C$4:$C$675,IF($B$4="TATA Order",'📋 ORDERS'!$D$4:$D$675,IF($B$4="Vulcan PO",'📋 ORDERS'!$E$4:$E$675,'📋 ORDERS'!$Q$4:$Q$675)))=$K$4),6),0)=0,"",IFERROR(INDEX('📋 ORDERS'!$R$4:$R$675,IFERROR(_xludf.aggregate(15,6,(ROW('📋 ORDERS'!$B$4:$B$675)-3)/(IF($B$4="SKF Order",'📋 ORDERS'!$C$4:$C$675,IF($B$4="TATA Order",'📋 ORDERS'!$D$4:$D$675,IF($B$4="Vulcan PO",'📋 ORDERS'!$E$4:$E$675,'📋 ORDERS'!$Q$4:$Q$675)))=$K$4),6),0)),"")) | J28: =IF(IFERROR(_xludf.aggregate(15,6,(ROW('📋 ORDERS'!$B$4:$B$675)-3)/(IF($B$4="SKF Order",'📋 ORDERS'!$C$4:$C$675,IF($B$4="TATA Order",'📋 ORDERS'!$D$4:$D$675,IF($B$4="Vulcan PO",'📋 ORDERS'!$E$4:$E$675,'📋 ORDERS'!$Q$4:$Q$675)))=$K$4),6),0)=0,"",IFERROR(INDEX('📋 ORDERS'!$S$4:$S$675,IFERROR(_xludf.aggregate(15,6,(ROW('📋 ORDERS'!$B$4:$B$675)-3)/(IF($B$4="SKF Order",'📋 ORDERS'!$C$4:$C$675,IF($B$4="TATA Order",'📋 ORDERS'!$D$4:$D$675,IF($B$4="Vulcan PO",'📋 ORDERS'!$E$4:$E$675,'📋 ORDERS'!$Q$4:$Q$675)))=$K$4),6),0)),""))
